Workbook

Sheet Tổng quan
A1: TỐI ƯU TÁC TỬ (AGENT) EIDE v3 — TỔNG QUAN
A2: Đối chiếu mã nguồn EIDE v3 (src/eide, ~70 nghìn dòng toàn dự án) với 18 mẫu kiến trúc agent trong tài liệu 'Kiến trúc AI Agent'. Ngày rà soát: 06/10/2026.
A4: 1. Số đề xuất theo mảng và mức ưu tiên
A5: Mảng | B5: P0 | C5: P1 | D5: P2 | E5: P3 | F5: Tổng
A6: 1. Lõi tác tử | B6: =COUNTIFS('Danh mục tối ưu'!$B$5:$B$110,$A6,'Danh mục tối ưu'!$K$5:$K$110,"P0") | C6: =COUNTIFS('Danh mục tối ưu'!$B$5:$B$110,$A6,'Danh mục tối ưu'!$K$5:$K$110,"P1") | D6: =COUNTIFS('Danh mục tối ưu'!$B$5:$B$110,$A6,'Danh mục tối ưu'!$K$5:$K$110,"P2") | E6: =COUNTIFS('Danh mục tối ưu'!$B$5:$B$110,$A6,'Danh mục tối ưu'!$K$5:$K$110,"P3") | F6: =SUM(B6:E6)
A7: 2. Phân tích & thiết kế phần mềm | B7: =COUNTIFS('Danh mục tối ưu'!$B$5:$B$110,$A7,'Danh mục tối ưu'!$K$5:$K$110,"P0") | C7: =COUNTIFS('Danh mục tối ưu'!$B$5:$B$110,$A7,'Danh mục tối ưu'!$K$5:$K$110,"P1") | D7: =COUNTIFS('Danh mục tối ưu'!$B$5:$B$110,$A7,'Danh mục tối ưu'!$K$5:$K$110,"P2") | E7: =COUNTIFS('Danh mục tối ưu'!$B$5:$B$110,$A7,'Danh mục tối ưu'!$K$5:$K$110,"P3") | F7: =SUM(B7:E7)
A8: 3. Mạch, ERC, HDL/FPGA | B8: =COUNTIFS('Danh mục tối ưu'!$B$5:$B$110,$A8,'Danh mục tối ưu'!$K$5:$K$110,"P0") | C8: =COUNTIFS('Danh mục tối ưu'!$B$5:$B$110,$A8,'Danh mục tối ưu'!$K$5:$K$110,"P1") | D8: =COUNTIFS('Danh mục tối ưu'!$B$5:$B$110,$A8,'Danh mục tối ưu'!$K$5:$K$110,"P2") | E8: =COUNTIFS('Danh mục tối ưu'!$B$5:$B$110,$A8,'Danh mục tối ưu'!$K$5:$K$110,"P3") | F8: =SUM(B8:E8)
A9: 4. Kiểm thử & kiểm chứng | B9: =COUNTIFS('Danh mục tối ưu'!$B$5:$B$110,$A9,'Danh mục tối ưu'!$K$5:$K$110,"P0") | C9: =COUNTIFS('Danh mục tối ưu'!$B$5:$B$110,$A9,'Danh mục tối ưu'!$K$5:$K$110,"P1") | D9: =COUNTIFS('Danh mục tối ưu'!$B$5:$B$110,$A9,'Danh mục tối ưu'!$K$5:$K$110,"P2") | E9: =COUNTIFS('Danh mục tối ưu'!$B$5:$B$110,$A9,'Danh mục tối ưu'!$K$5:$K$110,"P3") | F9: =SUM(B9:E9)
A10: 5. Tri thức, RAG & bộ nhớ | B10: =COUNTIFS('Danh mục tối ưu'!$B$5:$B$110,$A10,'Danh mục tối ưu'!$K$5:$K$110,"P0") | C10: =COUNTIFS('Danh mục tối ưu'!$B$5:$B$110,$A10,'Danh mục tối ưu'!$K$5:$K$110,"P1") | D10: =COUNTIFS('Danh mục tối ưu'!$B$5:$B$110,$A10,'Danh mục tối ưu'!$K$5:$K$110,"P2") | E10: =COUNTIFS('Danh mục tối ưu'!$B$5:$B$110,$A10,'Danh mục tối ưu'!$K$5:$K$110,"P3") | F10: =SUM(B10:E10)
A11: Tổng | B11: =SUM(B6:B10) | C11: =SUM(C6:C10) | D11: =SUM(D6:D10) | E11: =SUM(E6:E10) | F11: =SUM(F6:F10)
A13: 2. Lộ trình theo giai đoạn (tự tính từ Ưu tiên + Công sức)
A14: Giai đoạn | B14: Số đề xuất | C14: Đã xong | D14: % xong
A15: GĐ1 — Làm ngay (0–2 tuần): P0, công sức S/M | B15: =COUNTIF('Danh mục tối ưu'!$M$5:$M$110,"GĐ1") | C15: =COUNTIFS('Danh mục tối ưu'!$M$5:$M$110,"GĐ1",'Danh mục tối ưu'!$Q$5:$Q$110,"Xong") | D15: =IF(B15=0,0,C15/B15)
A16: GĐ2 — Ngắn hạn (2–6 tuần): P0 công sức L, P1 công sức S | B16: =COUNTIF('Danh mục tối ưu'!$M$5:$M$110,"GĐ2") | C16: =COUNTIFS('Danh mục tối ưu'!$M$5:$M$110,"GĐ2",'Danh mục tối ưu'!$Q$5:$Q$110,"Xong") | D16: =IF(B16=0,0,C16/B16)
A17: GĐ3 — Trung hạn (6–12 tuần): P1 công sức M/L | B17: =COUNTIF('Danh mục tối ưu'!$M$5:$M$110,"GĐ3") | C17: =COUNTIFS('Danh mục tối ưu'!$M$5:$M$110,"GĐ3",'Danh mục tối ưu'!$Q$5:$Q$110,"Xong") | D17: =IF(B17=0,0,C17/B17)
A18: GĐ4 — Có thì tốt: P2/P3 | B18: =COUNTIF('Danh mục tối ưu'!$M$5:$M$110,"GĐ4") | C18: =COUNTIFS('Danh mục tối ưu'!$M$5:$M$110,"GĐ4",'Danh mục tối ưu'!$Q$5:$Q$110,"Xong") | D18: =IF(B18=0,0,C18/B18)
A20: 3. Số đề xuất theo chủ đề xuyên suốt
A21: Chủ đề | B21: Số đề xuất | C21: Trong đó P0
A22: T01 Giao thức & độ bền vòng lặp | B22: =COUNTIF('Danh mục tối ưu'!$D$5:$D$110,$A22) | C22: =COUNTIFS('Danh mục tối ưu'!$D$5:$D$110,$A22,'Danh mục tối ưu'!$K$5:$K$110,"P0")
A23: T02 Ngữ cảnh, lược đồ công cụ & token | B23: =COUNTIF('Danh mục tối ưu'!$D$5:$D$110,$A23) | C23: =COUNTIFS('Danh mục tối ưu'!$D$5:$D$110,$A23,'Danh mục tối ưu'!$K$5:$K$110,"P0")
A24: T03 Tác tử con & điều phối song song | B24: =COUNTIF('Danh mục tối ưu'!$D$5:$D$110,$A24) | C24: =COUNTIFS('Danh mục tối ưu'!$D$5:$D$110,$A24,'Danh mục tối ưu'!$K$5:$K$110,"P0")
A25: T04 Kiểm chứng độc lập (verifier) | B25: =COUNTIF('Danh mục tối ưu'!$D$5:$D$110,$A25) | C25: =COUNTIFS('Danh mục tối ưu'!$D$5:$D$110,$A25,'Danh mục tối ưu'!$K$5:$K$110,"P0")
A26: T05 Lập kế hoạch & thực thi theo bước | B26: =COUNTIF('Danh mục tối ưu'!$D$5:$D$110,$A26) | C26: =COUNTIFS('Danh mục tối ưu'!$D$5:$D$110,$A26,'Danh mục tối ưu'!$K$5:$K$110,"P0")
A27: T06 Reflexion – bài học dài hạn | B27: =COUNTIF('Danh mục tối ưu'!$D$5:$D$110,$A27) | C27: =COUNTIFS('Danh mục tối ưu'!$D$5:$D$110,$A27,'Danh mục tối ưu'!$K$5:$K$110,"P0")
A28: T07 Phản biện thiết kế (Debate/ToT) | B28: =COUNTIF('Danh mục tối ưu'!$D$5:$D$110,$A28) | C28: =COUNTIFS('Danh mục tối ưu'!$D$5:$D$110,$A28,'Danh mục tối ưu'!$K$5:$K$110,"P0")
A29: T08 Yêu cầu & truy vết | B29: =COUNTIF('Danh mục tối ưu'!$D$5:$D$110,$A29) | C29: =COUNTIFS('Danh mục tối ưu'!$D$5:$D$110,$A29,'Danh mục tối ưu'!$K$5:$K$110,"P0")
A30: T09 Phân tích mã tĩnh & CodeAct | B30: =COUNTIF('Danh mục tối ưu'!$D$5:$D$110,$A30) | C30: =COUNTIFS('Danh mục tối ưu'!$D$5:$D$110,$A30,'Danh mục tối ưu'!$K$5:$K$110,"P0")
A31: T10 ERC & thiết kế mạch | B31: =COUNTIF('Danh mục tối ưu'!$D$5:$D$110,$A31) | C31: =COUNTIFS('Danh mục tối ưu'!$D$5:$D$110,$A31,'Danh mục tối ưu'!$K$5:$K$110,"P0")
A32: T11 HDL/FPGA | B32: =COUNTIF('Danh mục tối ưu'!$D$5:$D$110,$A32) | C32: =COUNTIFS('Danh mục tối ưu'!$D$5:$D$110,$A32,'Danh mục tối ưu'!$K$5:$K$110,"P0")
A33: T12 Kiểm thử sản phẩm (unit, đột biến, hồi quy, HIL) | B33: =COUNTIF('Danh mục tối ưu'!$D$5:$D$110,$A33) | C33: =COUNTIFS('Danh mục tối ưu'!$D$5:$D$110,$A33,'Danh mục tối ưu'!$K$5:$K$110,"P0")
... A36: T15 Đo lường & bộ đánh giá (eval) | B36: =COUNTIF('Danh mục tối ưu'!$D$5:$D$110,$A36) | C36: =COUNTIFS('Danh mục tối ưu'!$D$5:$D$110,$A36,'Danh mục tối ưu'!$K$5:$K$110,"P0")
A38: 4. Kết luận chính
A39: • Lõi đã có nền rất tốt: vòng ReAct qua ba lớp xác định (hook → policy → hook), thẻ duyệt người (HITL) R0–R4, plan mode khoá công cụ ghi, tiêu chí-trước cho mô phỏng có máy chấm bằng mã, ghi transcript trước (write-ahead), phát hiện quay vòng và lượt im lặng.
A40: • Ba lỗ hổng nền cần vá trước mọi tối ưu khác: (1) lịch sử gọi–trả công cụ lệch cặp với Gemini khi có thẻ cổng giữa lô; (2) tác tử con gọi thẳng registry.run, đi vòng qua hook/policy/plan mode; (3) hook Stop coi MỌI task.run là đã kiểm chứng.
A41: • Nhiều 'ô xanh giả' còn sót ở nơi chưa áp nguyên tắc 'chương trình đo, EIDE phán': unit test tự khai dat, PASS/FAIL HDL dò chuỗi con, độ nhạy HDL tự khai, đột biến không biên dịch được tính là 'bắt được', sch.netlist báo 0 lỗi trong khi phần lớn luật ERC 'chưa đủ dữ kiện'.
A42: • Khoảng trống lớn nhất so với 18 mẫu: Agentic RAG (chỉ có khớp chuỗi trong 1 tài liệu, không SVD, không bảng PDF), Reflexion (không có bài học dài hạn), Parallelization/LLMCompiler (mọi lời gọi tuần tự), Evaluator–Optimizer có vòng sửa (ERC, harden test, verifier bác).
A43: • Chi phí ngữ cảnh: 73 công cụ luôn hiện ≈ 26 nghìn token lược đồ mỗi lời gọi (gấp ~6,5 lần ngân sách 4000 khai trong config nhưng không dùng); khối nhắc mỗi lượt bị lưu lặp vĩnh viễn trong transcript; không có trần token mỗi lượt.
A44: • Mạch & HDL: ERC thiếu luật quá áp, kiểu chân, ngắn mạch nguồn, decoupling/boot; luồng HDL không có cổng giữa chặng, không kiểm ràng buộc chân .cst, không formal. Đây là nơi lỗi đắt nhất (hỏng phần cứng) mà hiện chỉ trông vào trí nhớ của mô hình.
A45: • Nguyên tắc leo thang: làm GĐ1 + bộ đo lường (T15) trước; chỉ thêm mẫu tốn kém (Debate, ToT, song song nhiều worker) khi số đo cho thấy bậc hiện tại chưa đủ.
A47: 5. Chú giải
...

Sheet Tiến độ 07-10-2026
A1: TIẾN ĐỘ ĐỢT TỐI ƯU TÁC TỬ — chốt ngày 07/10/2026
A2: Mỗi dòng 'Xong' đều có: mục DEV-LOG tra lại được · số ca kiểm trước→sau · một con số đo trên dữ liệu thật · phần còn nợ. Cột chi tiết nằm ở sheet “Danh mục tối ưu”, cột T–Y.
A4: Tổng quan | B4: Số việc | C4: Ghi chú
A5: Xong (đã gộp vào main, đã đẩy) | B5: 14 | C5: 14 việc đầu của Giai đoạn 1, theo đúng thứ tự # của kế hoạch
A6: Đang làm (chưa commit) | B6: 1 | C6: M3-13 — mã và ca kiểm đã có trên nhánh toi-uu/M3-13; còn chạy toàn bộ + DEV-LOG + commit
A7: Chưa làm | B7: 91 | C7: 91 việc còn lại trong 106
A8: TỔNG | B8: 106
A10: Phép đo của cả đợt | B10: Trước (06/10) | C10: Sau (07/10) | D10: Ghi chú
A11: Ca đơn vị Python (pytest -q) | B11: 1 610 | C11: 1 732 | D11: +122 ca; không ca cũ nào đỏ ở bất kỳ bước nào
A12: Ca đơn vị giao diện (swift test) | B12: 43 | C12: 43 | D12: không nhiệm vụ nào đụng ui/ — kiểu khối A2.2 dùng “table”, Swift đã dựng được
A13: kiem_tai_lieu.py | B13: 0 chỗ lệch | C13: 0 chỗ lệch | D13: bắt được 1 đường dẫn tôi ghi sai trong README, đã sửa
A14: thu_sch.py (cờ schematic bật) | B14: 63/63 | C14: 63/63 | D14: chạy ở M3-03 và M3-04, không tụt
A15: Mục DEV-LOG mới | B15: — | C15: DEV-330 → DEV-343 | D15: 14 mục, mỗi việc một mục
A16: Cờ tính năng mới | B16: 1 (schematic) | C16: 7 | D16: 6 cờ mới, TẤT CẢ mặc định TẮT
A17: Mã lỗi mới | B17: — | C17: E4031 · E4032 · E6012 | D17: lấy từ bảng cấp phát §6 của kế hoạch
A19: # | B19: Mã | C19: Mảng | D19: Ưu tiên | E19: DEV-LOG | F19: Ca kiểm | G19: Cờ mặc định
A20: 1 | B20: M1-01 | C20: 1. Lõi tác tử | D20: P0 | E20: DEV-330 | F20: 105/309 phiên thật có lịch sử tự mâu thuẫn — 255 chỗ (156 kết quả thứ hai cùng id, 74 message chen giữa, 24 kết quả lạc lượt, 1 lời gọi không kết quả) | G20: không có cờ — sửa lỗi thuần
A21: 2 | B21: M1-02 | C21: 1. Lõi tác tử | D21: P0 | E21: DEV-331 | F21: lược đồ công cụ thật: 25 869 token/lời gọi (trần tool_schema=4000 chưa dòng mã nào đọc). Cờ bật: 4 475 token, giảm 82,7 %; 73 → 18 công cụ | G21: GON_CONG_CU — TẮT
A22: 3 | B22: M1-03 | C22: 1. Lõi tác tử | D22: P0 | E22: DEV-332 | F22: 1 822 lời gọi của tác tử con trong 26 phiên thật, 0 lần qua lớp luật. Toàn công cụ đọc trừ một build.compile — lỗ hổng chưa bị bước vào, không phải được canh | G22: không có cờ — sửa lỗi thuần
A23: 4 | B23: M2-01 | C23: 2. Phân tích & thiết kế phần mềm | D23: P0 | E23: DEV-333 | F23: kịch bản 3 REQ + 3 phương án + 3 tiêu chí + 3 tệp: sửa MỘT REQ làm 9 hiện vật STALE → còn 3. Phép đo đầu ra 6→2 vì bị hàng rào E4020 chặn, đã sửa kịch bản đo | G23: TRUY_VET — TẮT (phần nền chạy cả khi tắt)
A24: 5 | B24: M2-02 | C24: 2. Phân tích & thiết kế phần mềm | D24: P0 | E24: DEV-334 | F24: 63 kho thật: 5/37 REQ có ít nhất một phép đo; 27 chưa có phương án nào nhận; 0 REQ đi hết chuỗi. Cột 'Mã nguồn' trống ở MỌI dự án vì hien_thuc_req vừa mới tồn tại | G24: REQ_PHU — TẮT (khối A2.2 trên tab không phụ thuộc cờ)
A25: 6 | B25: M2-03 | C25: 2. Phân tích & thiết kế phần mềm | D25: P0 | E25: DEV-335 | F25: 37 REQ thật: 25 sạch (67 %), 11 thiếu tiêu chí đo được, 2 có từ mơ hồ. Lần đo đầu ra 3 từ mơ hồ, một là kêu oan ('ít nhất 2 lần' là mức đo được) — đã vá | G25: REQ_CHAT_LUONG — TẮT (module yeu_cau.py luôn có)
A26: 7 | B26: M2-06 | C26: 2. Phân tích & thiết kế phần mềm | D26: P0 | E26: DEV-336 | F26: sổ cái thật: 26 lần đánh dấu 'xong' ngay sau một lần ghi mã, 19 lần (73 %) không có phép kiểm nào đạt ở giữa. Phép đo đầu ở mức dự án ra 0 — đúng nhưng đo sai câu hỏi | G26: KE_HOACH_CONG_KIEM — TẮT
A27: 8 | B27: M2-08 | C27: 2. Phân tích & thiết kế phần mềm | D27: P0 | E27: DEV-337 | F27: 185 tệp .c thật: 1 758 → 1 786 hàm thấy được (+28 hàm trước đây VÔ HÌNH: 8 ngắt + 20 bị regex tham lam nuốt). 78 hàm nay gắn nhãn 'isr', 70 trong đó vốn đã có trong danh sách | G27: không có cờ — sửa lỗi thuần
A28: 9 | B28: M3-01 | C28: 3. Mạch, ERC, HDL/FPGA | D28: P0 | E28: DEV-338 | F28: 0 phát hiện trên 5 mô hình mạch thật — và lý do đáng hơn con số: 3 kho CÓ Fact v_max thì KHÔNG có mô hình mạch, 5 kho có mạch thì không có Fact ấy; thêm nữa Fact dùng chủ thể chip:X mà ERC không tra tiền tố đó | G28: không có cờ — sửa lỗi thuần
A29: 10 | B29: M3-03 | C29: 3. Mạch, ERC, HDL/FPGA | D29: P0 | E29: DEV-339 | F29: 8 phát hiện trên 5 mạch thật (6 nguon_khong_cap + 2 net_mot_chan), trong đó net clock I2C nối đúng một chân. SÁU trong tám là 'mô hình chưa khai' chứ không phải 'mạch sai'. robot-canbang: 107 Port lá, KHÔNG Port nào là power_out | G29: không có cờ — sửa lỗi thuần
A30: 11 | B30: M3-04 | C30: 3. Mạch, ERC, HDL/FPGA | D30: P0 | E30: DEV-340 | F30: 0 phát hiện trên 5 mạch thật — và đây là con số ĐÚNG (hai lỗi này catastrophic, không bo nào sống tới lúc lưu kho). Đã CẤY hai bộ cấp vào bản sao kho robot-canbang để chứng minh luật sống: nổ đúng 1 blocker trên net +5V thật | G30: không có cờ — sửa lỗi thuần
A31: 12 | B31: M3-07 | C31: 3. Mạch, ERC, HDL/FPGA | D31: P0 | E31: DEV-341 | F31: Fact tới được ERC: 5 → 17 (+12). Ba kho có Fact datasheet thì TOÀN BỘ mang chủ thể chip:, tức trước đó không một Fact nào tới được ERC. Độ phủ 5 mạch thật nay đọc được | G31: không có cờ — sửa lỗi thuần
... A34: 15 | B34: M3-13 | C34: 3. Mạch, ERC, HDL/FPGA | D34: P0 | E34: chưa ghi | F34: testbench Verilog THẬT của bài 3 (lõi RISC-V): pcpi_dot4 bắt 1/1, pcpi_mac bắt 1/1 (phép phá 'đảo điều kiện if' làm bộ kiểm đỏ); pcpi_vmini CHƯA đo được — tb cần thêm mô-đun ram ngoài phần nó tự include | G34: không có cờ (công cụ mới core=False)
A36: Việc còn MỞ (ngoài 91 việc chưa làm) | B36: Vì sao còn mở
A37: Sáu cờ mới đều còn TẮT | B37: GON_CONG_CU · TRUY_VET · REQ_PHU · REQ_CHAT_LUONG · KE_HOACH_CONG_KIEM · ERC_TU_DONG. Cả sáu đổi thứ Agent nhìn thấy hoặc đọc mỗi lượt, nên chỉ bộ 76 ca chạy HAI chế độ mới nói được chúng làm Agent khá hơn hay tệ hơn — bộ ấy tốn tiền mô hình nên chưa chạy.
A38: kiem_cap_goi_tra() chưa thành hàng rào | B38: Soát được mọi phiên đã lưu, nhưng chưa hook nào gọi nó tự động — bắt được chuyện cũ, chưa chặn được chuyện mới.
A39: Luật ERC quá áp chưa nổ trên dữ liệu thật | B39: Đường dẫn đã thông ở M3-07, nhưng ba kho có Fact điện áp thì không có mô hình mạch, và ngược lại. Phải chờ một dự án có cả hai.
A40: Cột “Mã nguồn” của ma trận truy vết trống ở mọi dự án | B40: Nó đọc hien_thuc_req — trường vừa mới tồn tại, chưa tệp nào trên đĩa từng khai. Nên “chưa hiện thực” ở đó nghĩa là “chưa ai KHAI”, không phải “chưa ai viết”.
A41: Lỗi _go_dau trong src/eide/tools/design.py | B41: Viết .replace('d','d') nên 'ổn định' và 'ON DINH' không khớp nhau. Hàm ấy đang dùng cho một phép kiểm an toàn (người có thật sự chọn không). Tìm thấy ở M2-03, CHƯA sửa vì ngoài phạm vi — cần bộ ca kiểm riêng.
A42: subagent req-critic (bước 4 của M2-03) | B42: Kế hoạch ghi “tuỳ chọn, gộp M2-13”. Chưa làm, đúng theo kế hoạch.
A44: Lỗi tìm thấy trong CHÍNH PHÉP ĐO của tôi | B44: Lộ ra ở đâu
A45: Kịch bản đo bị hàng rào của sản phẩm chặn (ghi tệp chưa đọc, E4020) và trả về một con số hợp lý thay vì nổ — 6→2 trông đẹp y như 9→3 đúng | B45: M2-01 · DEV-333
A46: Ca kiểm dựng trên điều tôi tự nhớ sai: “thiết” bỏ dấu KHÔNG chứa “it”; chỗ va thật là bit/unit/init/exit | B46: M2-03 · DEV-335
A47: Phép phá dài ĐÚNG BẰNG mã gốc (0.6 → 0.0) nên __pycache__ cũ còn hiệu lực — phép đo chạy mã khác với mã trong tệp | B47: M2-03 · DEV-335
...

Sheet Tiến độ 08-10-2026
A1: TIẾN ĐỘ ĐỢT TỐI ƯU TÁC TỬ — chốt ngày 08/10/2026
A2: Mỗi dòng 'Xong' đều có: mục DEV-LOG tra lại được · số ca kiểm trước→sau · một con số đo trên dữ liệu thật · phần còn nợ. Cột chi tiết nằm ở sheet “Danh mục tối ưu”, cột T–Y.
A4: Tổng quan | B4: Số việc | C4: Ghi chú
A5: Xong (đã gộp vào main, đã đẩy) | B5: 16 | C5: 16 việc đầu của Giai đoạn 1, theo đúng thứ tự # của kế hoạch
A6: Đang làm (chưa commit) | B6: 0 | C6: không việc nào đang dở — M3-13 đã chốt và gộp main sáng 08/10
A7: Chưa làm | B7: 90 | C7: 90 việc còn lại trong 106
A8: TỔNG | B8: 106
A10: Phép đo của cả đợt | B10: Trước (06/10) | C10: Sau (08/10) | D10: Ghi chú
A11: Ca đơn vị Python (pytest -q) | B11: 1 610 | C11: 1 773 | D11: +163 ca so với 06/10; không ca cũ nào đỏ ở bất kỳ bước nào
A12: Ca đơn vị giao diện (swift test) | B12: 43 | C12: 43 | D12: không nhiệm vụ nào đụng ui/ — kiểu khối A2.2 dùng “table”, Swift đã dựng được
A13: kiem_tai_lieu.py | B13: 0 chỗ lệch | C13: 0 chỗ lệch | D13: 0 chỗ LỆCH CHẮC CHẮN cả hai lượt. Hôm nay nó bắt đúng chuyện cần bắt: hai công cụ mới làm README lệch số công cụ 127 → 129, và số 'cần đọc lại' nhảy 11 → 15 → về 11 sau khi sửa
A14: thu_sch.py (cờ schematic bật) | B14: 63/63 | C14: 63/63 | D14: chạy ở M3-03 và M3-04, không tụt
A15: Mục DEV-LOG mới | B15: — | C15: DEV-330 → DEV-345 | D15: 16 mục, mỗi việc một mục
A16: Cờ tính năng mới | B16: 1 (schematic) | C16: 7 | D16: 6 cờ mới, TẤT CẢ mặc định TẮT
A17: Mã lỗi mới | B17: — | C17: E4031 · E4032 · E6012 · E4033 | D17: E4033 của M3-18 KHÔNG lấy theo kế hoạch: tôi chọn E4031 trước, rồi grep thấy loop.py:1085 đã dùng E4031 cho 'chưa chạy, vì chờ cổng'
A19: # | B19: Mã | C19: Mảng | D19: Ưu tiên | E19: DEV-LOG | F19: Ca kiểm | G19: Cờ mặc định
A20: 1 | B20: M1-01 | C20: 1. Lõi tác tử | D20: P0 | E20: DEV-330 | F20: 105/309 phiên thật có lịch sử tự mâu thuẫn — 255 chỗ (156 kết quả thứ hai cùng id, 74 message chen giữa, 24 kết quả lạc lượt, 1 lời gọi không kết quả) | G20: không có cờ — sửa lỗi thuần
A21: 2 | B21: M1-02 | C21: 1. Lõi tác tử | D21: P0 | E21: DEV-331 | F21: lược đồ công cụ thật: 25 869 token/lời gọi (trần tool_schema=4000 chưa dòng mã nào đọc). Cờ bật: 4 475 token, giảm 82,7 %; 73 → 18 công cụ | G21: GON_CONG_CU — TẮT
A22: 3 | B22: M1-03 | C22: 1. Lõi tác tử | D22: P0 | E22: DEV-332 | F22: 1 822 lời gọi của tác tử con trong 26 phiên thật, 0 lần qua lớp luật. Toàn công cụ đọc trừ một build.compile — lỗ hổng chưa bị bước vào, không phải được canh | G22: không có cờ — sửa lỗi thuần
A23: 4 | B23: M2-01 | C23: 2. Phân tích & thiết kế phần mềm | D23: P0 | E23: DEV-333 | F23: kịch bản 3 REQ + 3 phương án + 3 tiêu chí + 3 tệp: sửa MỘT REQ làm 9 hiện vật STALE → còn 3. Phép đo đầu ra 6→2 vì bị hàng rào E4020 chặn, đã sửa kịch bản đo | G23: TRUY_VET — TẮT (phần nền chạy cả khi tắt)
A24: 5 | B24: M2-02 | C24: 2. Phân tích & thiết kế phần mềm | D24: P0 | E24: DEV-334 | F24: 63 kho thật: 5/37 REQ có ít nhất một phép đo; 27 chưa có phương án nào nhận; 0 REQ đi hết chuỗi. Cột 'Mã nguồn' trống ở MỌI dự án vì hien_thuc_req vừa mới tồn tại | G24: REQ_PHU — TẮT (khối A2.2 trên tab không phụ thuộc cờ)
A25: 6 | B25: M2-03 | C25: 2. Phân tích & thiết kế phần mềm | D25: P0 | E25: DEV-335 | F25: 37 REQ thật: 25 sạch (67 %), 11 thiếu tiêu chí đo được, 2 có từ mơ hồ. Lần đo đầu ra 3 từ mơ hồ, một là kêu oan ('ít nhất 2 lần' là mức đo được) — đã vá | G25: REQ_CHAT_LUONG — TẮT (module yeu_cau.py luôn có)
A26: 7 | B26: M2-06 | C26: 2. Phân tích & thiết kế phần mềm | D26: P0 | E26: DEV-336 | F26: sổ cái thật: 26 lần đánh dấu 'xong' ngay sau một lần ghi mã, 19 lần (73 %) không có phép kiểm nào đạt ở giữa. Phép đo đầu ở mức dự án ra 0 — đúng nhưng đo sai câu hỏi | G26: KE_HOACH_CONG_KIEM — TẮT
A27: 8 | B27: M2-08 | C27: 2. Phân tích & thiết kế phần mềm | D27: P0 | E27: DEV-337 | F27: 185 tệp .c thật: 1 758 → 1 786 hàm thấy được (+28 hàm trước đây VÔ HÌNH: 8 ngắt + 20 bị regex tham lam nuốt). 78 hàm nay gắn nhãn 'isr', 70 trong đó vốn đã có trong danh sách | G27: không có cờ — sửa lỗi thuần
A28: 9 | B28: M3-01 | C28: 3. Mạch, ERC, HDL/FPGA | D28: P0 | E28: DEV-338 | F28: 0 phát hiện trên 5 mô hình mạch thật — và lý do đáng hơn con số: 3 kho CÓ Fact v_max thì KHÔNG có mô hình mạch, 5 kho có mạch thì không có Fact ấy; thêm nữa Fact dùng chủ thể chip:X mà ERC không tra tiền tố đó | G28: không có cờ — sửa lỗi thuần
A29: 10 | B29: M3-03 | C29: 3. Mạch, ERC, HDL/FPGA | D29: P0 | E29: DEV-339 | F29: 8 phát hiện trên 5 mạch thật (6 nguon_khong_cap + 2 net_mot_chan), trong đó net clock I2C nối đúng một chân. SÁU trong tám là 'mô hình chưa khai' chứ không phải 'mạch sai'. robot-canbang: 107 Port lá, KHÔNG Port nào là power_out | G29: không có cờ — sửa lỗi thuần
A30: 11 | B30: M3-04 | C30: 3. Mạch, ERC, HDL/FPGA | D30: P0 | E30: DEV-340 | F30: 0 phát hiện trên 5 mạch thật — và đây là con số ĐÚNG (hai lỗi này catastrophic, không bo nào sống tới lúc lưu kho). Đã CẤY hai bộ cấp vào bản sao kho robot-canbang để chứng minh luật sống: nổ đúng 1 blocker trên net +5V thật | G30: không có cờ — sửa lỗi thuần
A31: 12 | B31: M3-07 | C31: 3. Mạch, ERC, HDL/FPGA | D31: P0 | E31: DEV-341 | F31: Fact tới được ERC: 5 → 17 (+12). Ba kho có Fact datasheet thì TOÀN BỘ mang chủ thể chip:, tức trước đó không một Fact nào tới được ERC. Độ phủ 5 mạch thật nay đọc được | G31: không có cờ — sửa lỗi thuần
... A34: 15 | B34: M3-13 | C34: 3. Mạch, ERC, HDL/FPGA | D34: P0 | E34: DEV-344 | F34: testbench Verilog THẬT của bài 3: tb_pcpi_dot4 1/1, tb_pcpi_mac 1/1, tb_pcpi_vmini không đo được (tb gọi bản bram HAI CỔNG đã bị bỏ 02/10) — mẫu số là TỆP, không phải phép phá | G34: không có cờ (công cụ mới core=False)
A35: 16 | B35: M3-18 | C35: 3. Mạch, ERC, HDL/FPGA | D35: P0 | E35: DEV-345 | F35: 6 cặp (mạng cổng, .cst) thật → 1 chỗ CHẶN: blinky của riscv-tn20k-b dựng bitstream 4,6 MB với chân đồng hồ do nextpnr tự chọn (rơi đúng chân 4 — bằng may). Cả 7 tệp .cst thật đọc hết, 0 lỗi cú pháp | G35: không có cờ (công cụ mới core=False)
A37: Việc còn MỞ (ngoài 90 việc chưa làm) | B37: Vì sao còn mở
A38: Sáu cờ mới đều còn TẮT | B38: GON_CONG_CU · TRUY_VET · REQ_PHU · REQ_CHAT_LUONG · KE_HOACH_CONG_KIEM · ERC_TU_DONG. Cả sáu đổi thứ Agent nhìn thấy hoặc đọc mỗi lượt, nên chỉ bộ 76 ca chạy HAI chế độ mới nói được chúng làm Agent khá hơn hay tệ hơn — bộ ấy tốn tiền mô hình nên chưa chạy.
A39: kiem_cap_goi_tra() chưa thành hàng rào | B39: Soát được mọi phiên đã lưu, nhưng chưa hook nào gọi nó tự động — bắt được chuyện cũ, chưa chặn được chuyện mới.
A40: Luật ERC quá áp chưa nổ trên dữ liệu thật | B40: Đường dẫn đã thông ở M3-07, nhưng ba kho có Fact điện áp thì không có mô hình mạch, và ngược lại. Phải chờ một dự án có cả hai.
A41: Cột “Mã nguồn” của ma trận truy vết trống ở mọi dự án | B41: Nó đọc hien_thuc_req — trường vừa mới tồn tại, chưa tệp nào trên đĩa từng khai. Nên “chưa hiện thực” ở đó nghĩa là “chưa ai KHAI”, không phải “chưa ai viết”.
A42: Lỗi _go_dau trong src/eide/tools/design.py | B42: Viết .replace('d','d') nên 'ổn định' và 'ON DINH' không khớp nhau. Hàm ấy đang dùng cho một phép kiểm an toàn (người có thật sự chọn không). Tìm thấy ở M2-03, CHƯA sửa vì ngoài phạm vi — cần bộ ca kiểm riêng.
A43: subagent req-critic (bước 4 của M2-03) | B43: Kế hoạch ghi “tuỳ chọn, gộp M2-13”. Chưa làm, đúng theo kế hoạch.
A44: Hai luật kiểm chân FPGA chưa có dữ liệu để nổ | B44: chan_lech_kit và io_type_lech_bank cần Fact chân kit. Không kho nào trong repo có Fact pin:tangnano20k.* hay khoá vccio — nên hôm nay chỉ 3 trong 5 luật của M3-18 kết luận được gì trên dữ liệu thật. Cùng hình dạng với luật ERC quá áp.
A45: Một bitstream cũ đã dựng với chân đồng hồ tự chọn | B45: blinky của du-lieu/riscv-tn20k-b — xem DEV-345 và README §8. Không sửa hiện vật cũ: đó là dữ liệu của những lượt đo đã chốt. Từ nay phép kiểm chặn trước nextpnr.
A46: Hai công cụ mới nhất chưa lượt Agent nào GỌI | B46: hdl.sensitivity và hdl.constraints_check: mã của cả hai đã chạy trên hiện vật thật, nhưng đó là tôi gọi hàm, không phải tác tử gọi công cụ. README §8 đếm cả hai vào phần chưa dùng thật.
...

Sheet Tiến độ 08-10-2026 (chiều)
A1: TIẾN ĐỘ ĐỢT TỐI ƯU TÁC TỬ — chốt chiều 08/10/2026
A2: Mỗi dòng 'Xong' đều có: mục DEV-LOG tra lại được · số ca kiểm trước→sau · một con số đo trên dữ liệu thật · phần còn nợ. Cột chi tiết nằm ở sheet “Danh mục tối ưu”, cột T–Y.
A4: Tổng quan | B4: Số việc | C4: Ghi chú
A5: Xong (đã gộp vào main, đã đẩy) | B5: 17 | C5: 17 việc đầu của Giai đoạn 1, theo đúng thứ tự # của kế hoạch
A6: Đang làm (chưa commit) | B6: 0 | C6: không việc nào đang dở
A7: Chưa làm | B7: 89 | C7: 89 việc còn lại trong 106
A8: TỔNG | B8: 106
A10: Phép đo của cả đợt | B10: Trước (06/10) | C10: Sau (08/10) | D10: Ghi chú
A11: Ca đơn vị Python (pytest -q) | B11: 1 610 | C11: 1 791 | D11: +181 ca so với 06/10; không ca cũ nào đỏ ở bất kỳ bước nào
A12: Ca đơn vị giao diện (swift test) | B12: 43 | C12: 43 | D12: không nhiệm vụ nào đụng ui/ — kiểu khối A2.2 dùng “table”, Swift đã dựng được
A13: kiem_tai_lieu.py | B13: 0 chỗ lệch | C13: 0 chỗ lệch | D13: 0 chỗ LỆCH CHẮC CHẮN cả hai lượt. Hôm nay nó bắt đúng chuyện cần bắt: hai công cụ mới làm README lệch số công cụ 127 → 129, và số 'cần đọc lại' nhảy 11 → 15 → về 11 sau khi sửa
A14: thu_sch.py (cờ schematic bật) | B14: 63/63 | C14: 63/63 | D14: chạy ở M3-03 và M3-04, không tụt
A15: Mục DEV-LOG mới | B15: — | C15: DEV-330 → DEV-346 | D15: 17 mục, mỗi việc một mục
A16: Cờ tính năng mới | B16: 1 (schematic) | C16: 7 | D16: 6 cờ mới, TẤT CẢ mặc định TẮT
A17: Mã lỗi mới | B17: — | C17: E4031 · E4032 · E6012 · E4033 · E4024 | D17: E4033 (M3-18) và E4024 (M4-01). M4-01 còn DÙNG LẠI E4008/E4009/E4023 của sim.run — cùng một chuyện thì cùng một mã, một mã mới cho cùng một chuyện là bắt người đọc học hai lần
A19: # | B19: Mã | C19: Mảng | D19: Ưu tiên | E19: DEV-LOG | F19: Ca kiểm | G19: Cờ mặc định
A20: 1 | B20: M1-01 | C20: 1. Lõi tác tử | D20: P0 | E20: DEV-330 | F20: 105/309 phiên thật có lịch sử tự mâu thuẫn — 255 chỗ (156 kết quả thứ hai cùng id, 74 message chen giữa, 24 kết quả lạc lượt, 1 lời gọi không kết quả) | G20: không có cờ — sửa lỗi thuần
A21: 2 | B21: M1-02 | C21: 1. Lõi tác tử | D21: P0 | E21: DEV-331 | F21: lược đồ công cụ thật: 25 869 token/lời gọi (trần tool_schema=4000 chưa dòng mã nào đọc). Cờ bật: 4 475 token, giảm 82,7 %; 73 → 18 công cụ | G21: GON_CONG_CU — TẮT
A22: 3 | B22: M1-03 | C22: 1. Lõi tác tử | D22: P0 | E22: DEV-332 | F22: 1 822 lời gọi của tác tử con trong 26 phiên thật, 0 lần qua lớp luật. Toàn công cụ đọc trừ một build.compile — lỗ hổng chưa bị bước vào, không phải được canh | G22: không có cờ — sửa lỗi thuần
A23: 4 | B23: M2-01 | C23: 2. Phân tích & thiết kế phần mềm | D23: P0 | E23: DEV-333 | F23: kịch bản 3 REQ + 3 phương án + 3 tiêu chí + 3 tệp: sửa MỘT REQ làm 9 hiện vật STALE → còn 3. Phép đo đầu ra 6→2 vì bị hàng rào E4020 chặn, đã sửa kịch bản đo | G23: TRUY_VET — TẮT (phần nền chạy cả khi tắt)
A24: 5 | B24: M2-02 | C24: 2. Phân tích & thiết kế phần mềm | D24: P0 | E24: DEV-334 | F24: 63 kho thật: 5/37 REQ có ít nhất một phép đo; 27 chưa có phương án nào nhận; 0 REQ đi hết chuỗi. Cột 'Mã nguồn' trống ở MỌI dự án vì hien_thuc_req vừa mới tồn tại | G24: REQ_PHU — TẮT (khối A2.2 trên tab không phụ thuộc cờ)
A25: 6 | B25: M2-03 | C25: 2. Phân tích & thiết kế phần mềm | D25: P0 | E25: DEV-335 | F25: 37 REQ thật: 25 sạch (67 %), 11 thiếu tiêu chí đo được, 2 có từ mơ hồ. Lần đo đầu ra 3 từ mơ hồ, một là kêu oan ('ít nhất 2 lần' là mức đo được) — đã vá | G25: REQ_CHAT_LUONG — TẮT (module yeu_cau.py luôn có)
A26: 7 | B26: M2-06 | C26: 2. Phân tích & thiết kế phần mềm | D26: P0 | E26: DEV-336 | F26: sổ cái thật: 26 lần đánh dấu 'xong' ngay sau một lần ghi mã, 19 lần (73 %) không có phép kiểm nào đạt ở giữa. Phép đo đầu ở mức dự án ra 0 — đúng nhưng đo sai câu hỏi | G26: KE_HOACH_CONG_KIEM — TẮT
A27: 8 | B27: M2-08 | C27: 2. Phân tích & thiết kế phần mềm | D27: P0 | E27: DEV-337 | F27: 185 tệp .c thật: 1 758 → 1 786 hàm thấy được (+28 hàm trước đây VÔ HÌNH: 8 ngắt + 20 bị regex tham lam nuốt). 78 hàm nay gắn nhãn 'isr', 70 trong đó vốn đã có trong danh sách | G27: không có cờ — sửa lỗi thuần
A28: 9 | B28: M3-01 | C28: 3. Mạch, ERC, HDL/FPGA | D28: P0 | E28: DEV-338 | F28: 0 phát hiện trên 5 mô hình mạch thật — và lý do đáng hơn con số: 3 kho CÓ Fact v_max thì KHÔNG có mô hình mạch, 5 kho có mạch thì không có Fact ấy; thêm nữa Fact dùng chủ thể chip:X mà ERC không tra tiền tố đó | G28: không có cờ — sửa lỗi thuần
A29: 10 | B29: M3-03 | C29: 3. Mạch, ERC, HDL/FPGA | D29: P0 | E29: DEV-339 | F29: 8 phát hiện trên 5 mạch thật (6 nguon_khong_cap + 2 net_mot_chan), trong đó net clock I2C nối đúng một chân. SÁU trong tám là 'mô hình chưa khai' chứ không phải 'mạch sai'. robot-canbang: 107 Port lá, KHÔNG Port nào là power_out | G29: không có cờ — sửa lỗi thuần
A30: 11 | B30: M3-04 | C30: 3. Mạch, ERC, HDL/FPGA | D30: P0 | E30: DEV-340 | F30: 0 phát hiện trên 5 mạch thật — và đây là con số ĐÚNG (hai lỗi này catastrophic, không bo nào sống tới lúc lưu kho). Đã CẤY hai bộ cấp vào bản sao kho robot-canbang để chứng minh luật sống: nổ đúng 1 blocker trên net +5V thật | G30: không có cờ — sửa lỗi thuần
A31: 12 | B31: M3-07 | C31: 3. Mạch, ERC, HDL/FPGA | D31: P0 | E31: DEV-341 | F31: Fact tới được ERC: 5 → 17 (+12). Ba kho có Fact datasheet thì TOÀN BỘ mang chủ thể chip:, tức trước đó không một Fact nào tới được ERC. Độ phủ 5 mạch thật nay đọc được | G31: không có cờ — sửa lỗi thuần
... A34: 15 | B34: M3-13 | C34: 3. Mạch, ERC, HDL/FPGA | D34: P0 | E34: DEV-344 | F34: testbench Verilog THẬT của bài 3: tb_pcpi_dot4 1/1, tb_pcpi_mac 1/1, tb_pcpi_vmini không đo được (tb gọi bản bram HAI CỔNG đã bị bỏ 02/10) — mẫu số là TỆP, không phải phép phá | G34: không có cờ (công cụ mới core=False)
A35: 16 | B35: M3-18 | C35: 3. Mạch, ERC, HDL/FPGA | D35: P0 | E35: DEV-345 | F35: 6 cặp (mạng cổng, .cst) thật → 1 chỗ CHẶN: blinky của riscv-tn20k-b dựng bitstream 4,6 MB với chân đồng hồ do nextpnr tự chọn (rơi đúng chân 4 — bằng may). Cả 7 tệp .cst thật đọc hết, 0 lỗi cú pháp | G35: không có cờ (công cụ mới core=False)
A36: 17 | B36: M4-01 | C36: 4. Kiểm thử & chất lượng | D36: P0 | E36: DEV-346 | F36: 18 ca chạy trình biên dịch C thật: tệp test in số đo {"T1":300} với ngưỡng <=255 → EIDE phán 1 ca HỎNG. Chưa kho cũ nào có tiêu chí unit test để đo lại trên dữ liệu thật | G36: không có cờ (công cụ mới core=False)
A38: Việc còn MỞ (ngoài 89 việc chưa làm) | B38: Vì sao còn mở
A39: Sáu cờ mới đều còn TẮT | B39: GON_CONG_CU · TRUY_VET · REQ_PHU · REQ_CHAT_LUONG · KE_HOACH_CONG_KIEM · ERC_TU_DONG. Cả sáu đổi thứ Agent nhìn thấy hoặc đọc mỗi lượt, nên chỉ bộ 76 ca chạy HAI chế độ mới nói được chúng làm Agent khá hơn hay tệ hơn — bộ ấy tốn tiền mô hình nên chưa chạy.
A40: kiem_cap_goi_tra() chưa thành hàng rào | B40: Soát được mọi phiên đã lưu, nhưng chưa hook nào gọi nó tự động — bắt được chuyện cũ, chưa chặn được chuyện mới.
A41: Luật ERC quá áp chưa nổ trên dữ liệu thật | B41: Đường dẫn đã thông ở M3-07, nhưng ba kho có Fact điện áp thì không có mô hình mạch, và ngược lại. Phải chờ một dự án có cả hai.
A42: Cột “Mã nguồn” của ma trận truy vết trống ở mọi dự án | B42: Nó đọc hien_thuc_req — trường vừa mới tồn tại, chưa tệp nào trên đĩa từng khai. Nên “chưa hiện thực” ở đó nghĩa là “chưa ai KHAI”, không phải “chưa ai viết”.
A43: Lỗi _go_dau trong src/eide/tools/design.py | B43: Viết .replace('d','d') nên 'ổn định' và 'ON DINH' không khớp nhau. Hàm ấy đang dùng cho một phép kiểm an toàn (người có thật sự chọn không). Tìm thấy ở M2-03, CHƯA sửa vì ngoài phạm vi — cần bộ ca kiểm riêng.
A44: subagent req-critic (bước 4 của M2-03) | B44: Kế hoạch ghi “tuỳ chọn, gộp M2-13”. Chưa làm, đúng theo kế hoạch.
A45: Hai luật kiểm chân FPGA chưa có dữ liệu để nổ | B45: chan_lech_kit và io_type_lech_bank cần Fact chân kit. Không kho nào trong repo có Fact pin:tangnano20k.* hay khoá vccio — nên hôm nay chỉ 3 trong 5 luật của M3-18 kết luận được gì trên dữ liệu thật. Cùng hình dạng với luật ERC quá áp.
A46: Một bitstream cũ đã dựng với chân đồng hồ tự chọn | B46: blinky của du-lieu/riscv-tn20k-b — xem DEV-345 và README §8. Không sửa hiện vật cũ: đó là dữ liệu của những lượt đo đã chốt. Từ nay phép kiểm chặn trước nextpnr.
...

Sheet Tiến độ 08-10-2026 (toi)
A1: TIẾN ĐỘ ĐỢT TỐI ƯU TÁC TỬ — chốt tối 08/10/2026
A2: Mỗi dòng 'Xong' đều có: mục DEV-LOG tra lại được · số ca kiểm trước→sau · một con số đo trên dữ liệu thật · phần còn nợ. Cột chi tiết nằm ở sheet “Danh mục tối ưu”, cột T–Y.
A4: Tổng quan | B4: Số việc | C4: Ghi chú
A5: Xong (đã gộp vào main, đã đẩy) | B5: 18 | C5: 18 việc đầu của Giai đoạn 1, theo đúng thứ tự # của kế hoạch
A6: Đang làm (chưa commit) | B6: 0 | C6: không việc nào đang dở
A7: Chưa làm | B7: 88 | C7: 88 việc còn lại trong 106
A8: TỔNG | B8: 106
A10: Phép đo của cả đợt | B10: Trước (06/10) | C10: Sau (08/10) | D10: Ghi chú
A11: Ca đơn vị Python (pytest -q) | B11: 1 610 | C11: 1 816 | D11: +206 ca so với 06/10; không ca cũ nào đỏ ở bất kỳ bước nào
A12: Ca đơn vị giao diện (swift test) | B12: 43 | C12: 43 | D12: không nhiệm vụ nào đụng ui/ — kiểu khối A2.2 dùng “table”, Swift đã dựng được
A13: kiem_tai_lieu.py | B13: 0 chỗ lệch | C13: 0 chỗ lệch | D13: 0 chỗ LỆCH CHẮC CHẮN cả hai lượt. Hôm nay nó bắt đúng chuyện cần bắt: hai công cụ mới làm README lệch số công cụ 127 → 129, và số 'cần đọc lại' nhảy 11 → 15 → về 11 sau khi sửa
A14: thu_sch.py (cờ schematic bật) | B14: 63/63 | C14: 63/63 | D14: chạy ở M3-03 và M3-04, không tụt
A15: Mục DEV-LOG mới | B15: — | C15: DEV-330 → DEV-347 | D15: 18 mục, mỗi việc một mục
A16: Cờ tính năng mới | B16: 1 (schematic) | C16: 8 | D16: 7 cờ mới, TẤT CẢ mặc định TẮT. Cờ thứ 7 là SIM_RUNNER_GIOI_HAN (M4-02) — nó giới hạn fs.write của sim-runner trong sim/; hàng rào chính của M4-02 (POL-N6-sua-test) thì KHÔNG sau cờ
A17: Mã lỗi mới | B17: — | C17: E4031 · E4032 · E6012 · E4033 · E4024 | D17: M4-02 không thêm mã nào: nó DÙNG LẠI E5006 cho cổng ghi của sim-runner. E4033 (M3-18), E4024 (M4-01)
A19: # | B19: Mã | C19: Mảng | D19: Ưu tiên | E19: DEV-LOG | F19: Ca kiểm | G19: Cờ mặc định
A20: 1 | B20: M1-01 | C20: 1. Lõi tác tử | D20: P0 | E20: DEV-330 | F20: 105/309 phiên thật có lịch sử tự mâu thuẫn — 255 chỗ (156 kết quả thứ hai cùng id, 74 message chen giữa, 24 kết quả lạc lượt, 1 lời gọi không kết quả) | G20: không có cờ — sửa lỗi thuần
A21: 2 | B21: M1-02 | C21: 1. Lõi tác tử | D21: P0 | E21: DEV-331 | F21: lược đồ công cụ thật: 25 869 token/lời gọi (trần tool_schema=4000 chưa dòng mã nào đọc). Cờ bật: 4 475 token, giảm 82,7 %; 73 → 18 công cụ | G21: GON_CONG_CU — TẮT
A22: 3 | B22: M1-03 | C22: 1. Lõi tác tử | D22: P0 | E22: DEV-332 | F22: 1 822 lời gọi của tác tử con trong 26 phiên thật, 0 lần qua lớp luật. Toàn công cụ đọc trừ một build.compile — lỗ hổng chưa bị bước vào, không phải được canh | G22: không có cờ — sửa lỗi thuần
A23: 4 | B23: M2-01 | C23: 2. Phân tích & thiết kế phần mềm | D23: P0 | E23: DEV-333 | F23: kịch bản 3 REQ + 3 phương án + 3 tiêu chí + 3 tệp: sửa MỘT REQ làm 9 hiện vật STALE → còn 3. Phép đo đầu ra 6→2 vì bị hàng rào E4020 chặn, đã sửa kịch bản đo | G23: TRUY_VET — TẮT (phần nền chạy cả khi tắt)
A24: 5 | B24: M2-02 | C24: 2. Phân tích & thiết kế phần mềm | D24: P0 | E24: DEV-334 | F24: 63 kho thật: 5/37 REQ có ít nhất một phép đo; 27 chưa có phương án nào nhận; 0 REQ đi hết chuỗi. Cột 'Mã nguồn' trống ở MỌI dự án vì hien_thuc_req vừa mới tồn tại | G24: REQ_PHU — TẮT (khối A2.2 trên tab không phụ thuộc cờ)
A25: 6 | B25: M2-03 | C25: 2. Phân tích & thiết kế phần mềm | D25: P0 | E25: DEV-335 | F25: 37 REQ thật: 25 sạch (67 %), 11 thiếu tiêu chí đo được, 2 có từ mơ hồ. Lần đo đầu ra 3 từ mơ hồ, một là kêu oan ('ít nhất 2 lần' là mức đo được) — đã vá | G25: REQ_CHAT_LUONG — TẮT (module yeu_cau.py luôn có)
A26: 7 | B26: M2-06 | C26: 2. Phân tích & thiết kế phần mềm | D26: P0 | E26: DEV-336 | F26: sổ cái thật: 26 lần đánh dấu 'xong' ngay sau một lần ghi mã, 19 lần (73 %) không có phép kiểm nào đạt ở giữa. Phép đo đầu ở mức dự án ra 0 — đúng nhưng đo sai câu hỏi | G26: KE_HOACH_CONG_KIEM — TẮT
A27: 8 | B27: M2-08 | C27: 2. Phân tích & thiết kế phần mềm | D27: P0 | E27: DEV-337 | F27: 185 tệp .c thật: 1 758 → 1 786 hàm thấy được (+28 hàm trước đây VÔ HÌNH: 8 ngắt + 20 bị regex tham lam nuốt). 78 hàm nay gắn nhãn 'isr', 70 trong đó vốn đã có trong danh sách | G27: không có cờ — sửa lỗi thuần
A28: 9 | B28: M3-01 | C28: 3. Mạch, ERC, HDL/FPGA | D28: P0 | E28: DEV-338 | F28: 0 phát hiện trên 5 mô hình mạch thật — và lý do đáng hơn con số: 3 kho CÓ Fact v_max thì KHÔNG có mô hình mạch, 5 kho có mạch thì không có Fact ấy; thêm nữa Fact dùng chủ thể chip:X mà ERC không tra tiền tố đó | G28: không có cờ — sửa lỗi thuần
A29: 10 | B29: M3-03 | C29: 3. Mạch, ERC, HDL/FPGA | D29: P0 | E29: DEV-339 | F29: 8 phát hiện trên 5 mạch thật (6 nguon_khong_cap + 2 net_mot_chan), trong đó net clock I2C nối đúng một chân. SÁU trong tám là 'mô hình chưa khai' chứ không phải 'mạch sai'. robot-canbang: 107 Port lá, KHÔNG Port nào là power_out | G29: không có cờ — sửa lỗi thuần
A30: 11 | B30: M3-04 | C30: 3. Mạch, ERC, HDL/FPGA | D30: P0 | E30: DEV-340 | F30: 0 phát hiện trên 5 mạch thật — và đây là con số ĐÚNG (hai lỗi này catastrophic, không bo nào sống tới lúc lưu kho). Đã CẤY hai bộ cấp vào bản sao kho robot-canbang để chứng minh luật sống: nổ đúng 1 blocker trên net +5V thật | G30: không có cờ — sửa lỗi thuần
A31: 12 | B31: M3-07 | C31: 3. Mạch, ERC, HDL/FPGA | D31: P0 | E31: DEV-341 | F31: Fact tới được ERC: 5 → 17 (+12). Ba kho có Fact datasheet thì TOÀN BỘ mang chủ thể chip:, tức trước đó không một Fact nào tới được ERC. Độ phủ 5 mạch thật nay đọc được | G31: không có cờ — sửa lỗi thuần
... A34: 15 | B34: M3-13 | C34: 3. Mạch, ERC, HDL/FPGA | D34: P0 | E34: DEV-344 | F34: testbench Verilog THẬT của bài 3: tb_pcpi_dot4 1/1, tb_pcpi_mac 1/1, tb_pcpi_vmini không đo được (tb gọi bản bram HAI CỔNG đã bị bỏ 02/10) — mẫu số là TỆP, không phải phép phá | G34: không có cờ (công cụ mới core=False)
A35: 16 | B35: M3-18 | C35: 3. Mạch, ERC, HDL/FPGA | D35: P0 | E35: DEV-345 | F35: 6 cặp (mạng cổng, .cst) thật → 1 chỗ CHẶN: blinky của riscv-tn20k-b dựng bitstream 4,6 MB với chân đồng hồ do nextpnr tự chọn (rơi đúng chân 4 — bằng may). Cả 7 tệp .cst thật đọc hết, 0 lỗi cú pháp | G35: không có cờ (công cụ mới core=False)
A36: 17 | B36: M4-01 | C36: 4. Kiểm thử & chất lượng | D36: P0 | E36: DEV-346 | F36: 18 ca chạy trình biên dịch C thật: tệp test in số đo {"T1":300} với ngưỡng <=255 → EIDE phán 1 ca HỎNG. Chưa kho cũ nào có tiêu chí unit test để đo lại trên dữ liệu thật | G36: không có cờ (công cụ mới core=False)
A37: 18 | B37: M4-02 | C37: 4. Kiểm thử & chất lượng | D37: P0 | E37: DEV-347 | F37: 25 ca dựng đúng trạng thái thật (tệp test 3 ca, 1 ca đỏ, hiện vật dat=False) → fs.write còn 1 ca thì test.weakened=True. Và hàng rào cũ criteria.has_result chưa bao giờ nổ ngoài sim-01 | G37: SIM_RUNNER_GIOI_HAN — TẮT
A39: Việc còn MỞ (ngoài 88 việc chưa làm) | B39: Vì sao còn mở
A40: Bảy cờ mới đều còn TẮT | B40: GON_CONG_CU · TRUY_VET · REQ_PHU · REQ_CHAT_LUONG · KE_HOACH_CONG_KIEM · ERC_TU_DONG · SIM_RUNNER_GIOI_HAN. Cả bảy đổi thứ Agent nhìn thấy, đọc, hoặc LÀM ĐƯỢC mỗi lượt, nên chỉ bộ 76 ca chạy hai chế độ mới nói được chúng làm Agent khá hơn hay tệ hơn. Bộ ấy tốn tiền mô hình nên §3.0 bắt hỏi người dùng trước.
A41: kiem_cap_goi_tra() chưa thành hàng rào | B41: Soát được mọi phiên đã lưu, nhưng chưa hook nào gọi nó tự động — bắt được chuyện cũ, chưa chặn được chuyện mới.
A42: Luật ERC quá áp chưa nổ trên dữ liệu thật | B42: Đường dẫn đã thông ở M3-07, nhưng ba kho có Fact điện áp thì không có mô hình mạch, và ngược lại. Phải chờ một dự án có cả hai.
A43: Cột “Mã nguồn” của ma trận truy vết trống ở mọi dự án | B43: Nó đọc hien_thuc_req — trường vừa mới tồn tại, chưa tệp nào trên đĩa từng khai. Nên “chưa hiện thực” ở đó nghĩa là “chưa ai KHAI”, không phải “chưa ai viết”.
A44: Lỗi _go_dau trong src/eide/tools/design.py | B44: Viết .replace('d','d') nên 'ổn định' và 'ON DINH' không khớp nhau. Hàm ấy đang dùng cho một phép kiểm an toàn (người có thật sự chọn không). Tìm thấy ở M2-03, CHƯA sửa vì ngoài phạm vi — cần bộ ca kiểm riêng.
A45: subagent req-critic (bước 4 của M2-03) | B45: Kế hoạch ghi “tuỳ chọn, gộp M2-13”. Chưa làm, đúng theo kế hoạch.
A46: Hai luật kiểm chân FPGA chưa có dữ liệu để nổ | B46: chan_lech_kit và io_type_lech_bank cần Fact chân kit. Không kho nào trong repo có Fact pin:tangnano20k.* hay khoá vccio — nên hôm nay chỉ 3 trong 5 luật của M3-18 kết luận được gì trên dữ liệu thật. Cùng hình dạng với luật ERC quá áp.
...

Sheet Tiến độ 08-10-2026 (khuya)
A1: TIẾN ĐỘ ĐỢT TỐI ƯU TÁC TỬ — chốt khuya 08/10/2026
A2: Mỗi dòng 'Xong' đều có: mục DEV-LOG tra lại được · số ca kiểm trước→sau · một con số đo trên dữ liệu thật · phần còn nợ. Cột chi tiết nằm ở sheet “Danh mục tối ưu”, cột T–Y.
A4: Tổng quan | B4: Số việc | C4: Ghi chú
A5: Xong (đã gộp vào main, đã đẩy) | B5: 19 | C5: 19 việc đầu của Giai đoạn 1, theo đúng thứ tự # của kế hoạch
A6: Đang làm (chưa commit) | B6: 0 | C6: không việc nào đang dở
A7: Chưa làm | B7: 87 | C7: 87 việc còn lại trong 106
A8: TỔNG | B8: 106
A10: Phép đo của cả đợt | B10: Trước (06/10) | C10: Sau (08/10) | D10: Ghi chú
A11: Ca đơn vị Python (pytest -q) | B11: 1 610 | C11: 1 835 | D11: +225 ca so với 06/10; không ca cũ nào đỏ ở bất kỳ bước nào
A12: Ca đơn vị giao diện (swift test) | B12: 43 | C12: 43 | D12: không nhiệm vụ nào đụng ui/ — kiểu khối A2.2 dùng “table”, Swift đã dựng được
A13: kiem_tai_lieu.py | B13: 0 chỗ lệch | C13: 0 chỗ lệch | D13: 0 chỗ LỆCH CHẮC CHẮN cả hai lượt. Hôm nay nó bắt đúng chuyện cần bắt: hai công cụ mới làm README lệch số công cụ 127 → 129, và số 'cần đọc lại' nhảy 11 → 15 → về 11 sau khi sửa
A14: thu_sch.py (cờ schematic bật) | B14: 63/63 | C14: 63/63 | D14: chạy ở M3-03 và M3-04, không tụt
A15: Mục DEV-LOG mới | B15: — | C15: DEV-330 → DEV-348 | D15: 19 mục, mỗi việc một mục
A16: Cờ tính năng mới | B16: 1 (schematic) | C16: 8 | D16: 7 cờ mới, TẤT CẢ mặc định TẮT. Cờ thứ 7 là SIM_RUNNER_GIOI_HAN (M4-02) — nó giới hạn fs.write của sim-runner trong sim/; hàng rào chính của M4-02 (POL-N6-sua-test) thì KHÔNG sau cờ
A17: Mã lỗi mới | B17: — | C17: E4031 · E4032 · E6012 · E4033 · E4024 | D17: M4-05 không thêm mã nào. M4-02 cũng không (dùng lại E5006). E4033 (M3-18), E4024 (M4-01)
A19: # | B19: Mã | C19: Mảng | D19: Ưu tiên | E19: DEV-LOG | F19: Ca kiểm | G19: Cờ mặc định
A20: 1 | B20: M1-01 | C20: 1. Lõi tác tử | D20: P0 | E20: DEV-330 | F20: 105/309 phiên thật có lịch sử tự mâu thuẫn — 255 chỗ (156 kết quả thứ hai cùng id, 74 message chen giữa, 24 kết quả lạc lượt, 1 lời gọi không kết quả) | G20: không có cờ — sửa lỗi thuần
A21: 2 | B21: M1-02 | C21: 1. Lõi tác tử | D21: P0 | E21: DEV-331 | F21: lược đồ công cụ thật: 25 869 token/lời gọi (trần tool_schema=4000 chưa dòng mã nào đọc). Cờ bật: 4 475 token, giảm 82,7 %; 73 → 18 công cụ | G21: GON_CONG_CU — TẮT
A22: 3 | B22: M1-03 | C22: 1. Lõi tác tử | D22: P0 | E22: DEV-332 | F22: 1 822 lời gọi của tác tử con trong 26 phiên thật, 0 lần qua lớp luật. Toàn công cụ đọc trừ một build.compile — lỗ hổng chưa bị bước vào, không phải được canh | G22: không có cờ — sửa lỗi thuần
A23: 4 | B23: M2-01 | C23: 2. Phân tích & thiết kế phần mềm | D23: P0 | E23: DEV-333 | F23: kịch bản 3 REQ + 3 phương án + 3 tiêu chí + 3 tệp: sửa MỘT REQ làm 9 hiện vật STALE → còn 3. Phép đo đầu ra 6→2 vì bị hàng rào E4020 chặn, đã sửa kịch bản đo | G23: TRUY_VET — TẮT (phần nền chạy cả khi tắt)
A24: 5 | B24: M2-02 | C24: 2. Phân tích & thiết kế phần mềm | D24: P0 | E24: DEV-334 | F24: 63 kho thật: 5/37 REQ có ít nhất một phép đo; 27 chưa có phương án nào nhận; 0 REQ đi hết chuỗi. Cột 'Mã nguồn' trống ở MỌI dự án vì hien_thuc_req vừa mới tồn tại | G24: REQ_PHU — TẮT (khối A2.2 trên tab không phụ thuộc cờ)
A25: 6 | B25: M2-03 | C25: 2. Phân tích & thiết kế phần mềm | D25: P0 | E25: DEV-335 | F25: 37 REQ thật: 25 sạch (67 %), 11 thiếu tiêu chí đo được, 2 có từ mơ hồ. Lần đo đầu ra 3 từ mơ hồ, một là kêu oan ('ít nhất 2 lần' là mức đo được) — đã vá | G25: REQ_CHAT_LUONG — TẮT (module yeu_cau.py luôn có)
A26: 7 | B26: M2-06 | C26: 2. Phân tích & thiết kế phần mềm | D26: P0 | E26: DEV-336 | F26: sổ cái thật: 26 lần đánh dấu 'xong' ngay sau một lần ghi mã, 19 lần (73 %) không có phép kiểm nào đạt ở giữa. Phép đo đầu ở mức dự án ra 0 — đúng nhưng đo sai câu hỏi | G26: KE_HOACH_CONG_KIEM — TẮT
A27: 8 | B27: M2-08 | C27: 2. Phân tích & thiết kế phần mềm | D27: P0 | E27: DEV-337 | F27: 185 tệp .c thật: 1 758 → 1 786 hàm thấy được (+28 hàm trước đây VÔ HÌNH: 8 ngắt + 20 bị regex tham lam nuốt). 78 hàm nay gắn nhãn 'isr', 70 trong đó vốn đã có trong danh sách | G27: không có cờ — sửa lỗi thuần
A28: 9 | B28: M3-01 | C28: 3. Mạch, ERC, HDL/FPGA | D28: P0 | E28: DEV-338 | F28: 0 phát hiện trên 5 mô hình mạch thật — và lý do đáng hơn con số: 3 kho CÓ Fact v_max thì KHÔNG có mô hình mạch, 5 kho có mạch thì không có Fact ấy; thêm nữa Fact dùng chủ thể chip:X mà ERC không tra tiền tố đó | G28: không có cờ — sửa lỗi thuần
A29: 10 | B29: M3-03 | C29: 3. Mạch, ERC, HDL/FPGA | D29: P0 | E29: DEV-339 | F29: 8 phát hiện trên 5 mạch thật (6 nguon_khong_cap + 2 net_mot_chan), trong đó net clock I2C nối đúng một chân. SÁU trong tám là 'mô hình chưa khai' chứ không phải 'mạch sai'. robot-canbang: 107 Port lá, KHÔNG Port nào là power_out | G29: không có cờ — sửa lỗi thuần
A30: 11 | B30: M3-04 | C30: 3. Mạch, ERC, HDL/FPGA | D30: P0 | E30: DEV-340 | F30: 0 phát hiện trên 5 mạch thật — và đây là con số ĐÚNG (hai lỗi này catastrophic, không bo nào sống tới lúc lưu kho). Đã CẤY hai bộ cấp vào bản sao kho robot-canbang để chứng minh luật sống: nổ đúng 1 blocker trên net +5V thật | G30: không có cờ — sửa lỗi thuần
A31: 12 | B31: M3-07 | C31: 3. Mạch, ERC, HDL/FPGA | D31: P0 | E31: DEV-341 | F31: Fact tới được ERC: 5 → 17 (+12). Ba kho có Fact datasheet thì TOÀN BỘ mang chủ thể chip:, tức trước đó không một Fact nào tới được ERC. Độ phủ 5 mạch thật nay đọc được | G31: không có cờ — sửa lỗi thuần
... A34: 15 | B34: M3-13 | C34: 3. Mạch, ERC, HDL/FPGA | D34: P0 | E34: DEV-344 | F34: testbench Verilog THẬT của bài 3: tb_pcpi_dot4 1/1, tb_pcpi_mac 1/1, tb_pcpi_vmini không đo được (tb gọi bản bram HAI CỔNG đã bị bỏ 02/10) — mẫu số là TỆP, không phải phép phá | G34: không có cờ (công cụ mới core=False)
A35: 16 | B35: M3-18 | C35: 3. Mạch, ERC, HDL/FPGA | D35: P0 | E35: DEV-345 | F35: 6 cặp (mạng cổng, .cst) thật → 1 chỗ CHẶN: blinky của riscv-tn20k-b dựng bitstream 4,6 MB với chân đồng hồ do nextpnr tự chọn (rơi đúng chân 4 — bằng may). Cả 7 tệp .cst thật đọc hết, 0 lỗi cú pháp | G35: không có cờ (công cụ mới core=False)
A36: 17 | B36: M4-01 | C36: 4. Kiểm thử & chất lượng | D36: P0 | E36: DEV-346 | F36: 18 ca chạy trình biên dịch C thật: tệp test in số đo {"T1":300} với ngưỡng <=255 → EIDE phán 1 ca HỎNG. Chưa kho cũ nào có tiêu chí unit test để đo lại trên dữ liệu thật | G36: không có cờ (công cụ mới core=False)
A37: 18 | B37: M4-02 | C37: 4. Kiểm thử & chất lượng | D37: P0 | E37: DEV-347 | F37: 25 ca dựng đúng trạng thái thật (tệp test 3 ca, 1 ca đỏ, hiện vật dat=False) → fs.write còn 1 ca thì test.weakened=True. Và hàng rào cũ criteria.has_result chưa bao giờ nổ ngoài sim-01 | G37: SIM_RUNNER_GIOI_HAN — TẮT
A38: 19 | B38: M4-05 | C38: 4. Kiểm thử & chất lượng | D38: P1 | E38: DEV-348 | F38: du-lieu/rtos-sinhvien, chạy CẢ HAI hành vi: cũ so_thay=1, mới so_thay=0 — logo_ptit.c từ 'bộ kiểm ĐỎ' thành 'mọi đột biến đều làm hỏng biên dịch'. Một ô xanh giả, đã sửa | G38: không có cờ — sửa lỗi thuần
A40: Việc còn MỞ (ngoài 87 việc chưa làm) | B40: Vì sao còn mở
A41: Bảy cờ mới đều còn TẮT | B41: GON_CONG_CU · TRUY_VET · REQ_PHU · REQ_CHAT_LUONG · KE_HOACH_CONG_KIEM · ERC_TU_DONG · SIM_RUNNER_GIOI_HAN. Cả bảy đổi thứ Agent nhìn thấy, đọc, hoặc LÀM ĐƯỢC mỗi lượt, nên chỉ bộ 76 ca chạy hai chế độ mới nói được chúng làm Agent khá hơn hay tệ hơn. Bộ ấy tốn tiền mô hình nên §3.0 bắt hỏi người dùng trước.
A42: kiem_cap_goi_tra() chưa thành hàng rào | B42: Soát được mọi phiên đã lưu, nhưng chưa hook nào gọi nó tự động — bắt được chuyện cũ, chưa chặn được chuyện mới.
A43: Luật ERC quá áp chưa nổ trên dữ liệu thật | B43: Đường dẫn đã thông ở M3-07, nhưng ba kho có Fact điện áp thì không có mô hình mạch, và ngược lại. Phải chờ một dự án có cả hai.
A44: Cột “Mã nguồn” của ma trận truy vết trống ở mọi dự án | B44: Nó đọc hien_thuc_req — trường vừa mới tồn tại, chưa tệp nào trên đĩa từng khai. Nên “chưa hiện thực” ở đó nghĩa là “chưa ai KHAI”, không phải “chưa ai viết”.
A45: Lỗi _go_dau trong src/eide/tools/design.py | B45: Viết .replace('d','d') nên 'ổn định' và 'ON DINH' không khớp nhau. Hàm ấy đang dùng cho một phép kiểm an toàn (người có thật sự chọn không). Tìm thấy ở M2-03, CHƯA sửa vì ngoài phạm vi — cần bộ ca kiểm riêng.
A46: subagent req-critic (bước 4 của M2-03) | B46: Kế hoạch ghi “tuỳ chọn, gộp M2-13”. Chưa làm, đúng theo kế hoạch.
...

Sheet Tiến độ 09-10-2026
A1: TIẾN ĐỘ ĐỢT TỐI ƯU TÁC TỬ — chốt ngày 09/10/2026
A2: Mỗi dòng 'Xong' đều có: mục DEV-LOG tra lại được · số ca kiểm trước→sau · một con số đo trên dữ liệu thật · phần còn nợ. Cột chi tiết nằm ở sheet “Danh mục tối ưu”, cột T–Y.
A4: Tổng quan | B4: Số việc | C4: Ghi chú
A5: Xong (đã gộp vào main, đã đẩy) | B5: 20 | C5: 20 việc đầu của Giai đoạn 1, theo đúng thứ tự # của kế hoạch
A6: Đang làm (chưa commit) | B6: 0 | C6: không việc nào đang dở
A7: Chưa làm | B7: 86 | C7: 86 việc còn lại trong 106
A8: TỔNG | B8: 106
A10: Phép đo của cả đợt | B10: Trước (06/10) | C10: Sau (08/10) | D10: Ghi chú
A11: Ca đơn vị Python (pytest -q) | B11: 1 610 | C11: 1 846 | D11: +236 ca so với 06/10; không ca cũ nào đỏ ở bất kỳ bước nào
A12: Ca đơn vị giao diện (swift test) | B12: 43 | C12: 43 | D12: không nhiệm vụ nào đụng ui/ — kiểu khối A2.2 dùng “table”, Swift đã dựng được
A13: kiem_tai_lieu.py | B13: 0 chỗ lệch | C13: 0 chỗ lệch | D13: 0 chỗ LỆCH CHẮC CHẮN cả hai lượt. Hôm nay nó bắt đúng chuyện cần bắt: hai công cụ mới làm README lệch số công cụ 127 → 129, và số 'cần đọc lại' nhảy 11 → 15 → về 11 sau khi sửa
A14: thu_sch.py (cờ schematic bật) | B14: 63/63 | C14: 63/63 | D14: chạy ở M3-03 và M3-04, không tụt
A15: Mục DEV-LOG mới | B15: — | C15: DEV-330 → DEV-349 | D15: 20 mục, mỗi việc một mục
A16: Cờ tính năng mới | B16: 1 (schematic) | C16: 8 | D16: 7 cờ mới, TẤT CẢ mặc định TẮT. Cờ thứ 7 là SIM_RUNNER_GIOI_HAN (M4-02) — nó giới hạn fs.write của sim-runner trong sim/; hàng rào chính của M4-02 (POL-N6-sua-test) thì KHÔNG sau cờ
A17: Mã lỗi mới | B17: — | C17: E4031 · E4032 · E6012 · E4033 · E4024 | D17: M4-05 không thêm mã nào. M4-02 cũng không (dùng lại E5006). E4033 (M3-18), E4024 (M4-01)
A19: # | B19: Mã | C19: Mảng | D19: Ưu tiên | E19: DEV-LOG | F19: Ca kiểm | G19: Cờ mặc định
A20: 1 | B20: M1-01 | C20: 1. Lõi tác tử | D20: P0 | E20: DEV-330 | F20: 105/309 phiên thật có lịch sử tự mâu thuẫn — 255 chỗ (156 kết quả thứ hai cùng id, 74 message chen giữa, 24 kết quả lạc lượt, 1 lời gọi không kết quả) | G20: không có cờ — sửa lỗi thuần
A21: 2 | B21: M1-02 | C21: 1. Lõi tác tử | D21: P0 | E21: DEV-331 | F21: lược đồ công cụ thật: 25 869 token/lời gọi (trần tool_schema=4000 chưa dòng mã nào đọc). Cờ bật: 4 475 token, giảm 82,7 %; 73 → 18 công cụ | G21: GON_CONG_CU — TẮT
A22: 3 | B22: M1-03 | C22: 1. Lõi tác tử | D22: P0 | E22: DEV-332 | F22: 1 822 lời gọi của tác tử con trong 26 phiên thật, 0 lần qua lớp luật. Toàn công cụ đọc trừ một build.compile — lỗ hổng chưa bị bước vào, không phải được canh | G22: không có cờ — sửa lỗi thuần
A23: 4 | B23: M2-01 | C23: 2. Phân tích & thiết kế phần mềm | D23: P0 | E23: DEV-333 | F23: kịch bản 3 REQ + 3 phương án + 3 tiêu chí + 3 tệp: sửa MỘT REQ làm 9 hiện vật STALE → còn 3. Phép đo đầu ra 6→2 vì bị hàng rào E4020 chặn, đã sửa kịch bản đo | G23: TRUY_VET — TẮT (phần nền chạy cả khi tắt)
A24: 5 | B24: M2-02 | C24: 2. Phân tích & thiết kế phần mềm | D24: P0 | E24: DEV-334 | F24: 63 kho thật: 5/37 REQ có ít nhất một phép đo; 27 chưa có phương án nào nhận; 0 REQ đi hết chuỗi. Cột 'Mã nguồn' trống ở MỌI dự án vì hien_thuc_req vừa mới tồn tại | G24: REQ_PHU — TẮT (khối A2.2 trên tab không phụ thuộc cờ)
A25: 6 | B25: M2-03 | C25: 2. Phân tích & thiết kế phần mềm | D25: P0 | E25: DEV-335 | F25: 37 REQ thật: 25 sạch (67 %), 11 thiếu tiêu chí đo được, 2 có từ mơ hồ. Lần đo đầu ra 3 từ mơ hồ, một là kêu oan ('ít nhất 2 lần' là mức đo được) — đã vá | G25: REQ_CHAT_LUONG — TẮT (module yeu_cau.py luôn có)
A26: 7 | B26: M2-06 | C26: 2. Phân tích & thiết kế phần mềm | D26: P0 | E26: DEV-336 | F26: sổ cái thật: 26 lần đánh dấu 'xong' ngay sau một lần ghi mã, 19 lần (73 %) không có phép kiểm nào đạt ở giữa. Phép đo đầu ở mức dự án ra 0 — đúng nhưng đo sai câu hỏi | G26: KE_HOACH_CONG_KIEM — TẮT
A27: 8 | B27: M2-08 | C27: 2. Phân tích & thiết kế phần mềm | D27: P0 | E27: DEV-337 | F27: 185 tệp .c thật: 1 758 → 1 786 hàm thấy được (+28 hàm trước đây VÔ HÌNH: 8 ngắt + 20 bị regex tham lam nuốt). 78 hàm nay gắn nhãn 'isr', 70 trong đó vốn đã có trong danh sách | G27: không có cờ — sửa lỗi thuần
A28: 9 | B28: M3-01 | C28: 3. Mạch, ERC, HDL/FPGA | D28: P0 | E28: DEV-338 | F28: 0 phát hiện trên 5 mô hình mạch thật — và lý do đáng hơn con số: 3 kho CÓ Fact v_max thì KHÔNG có mô hình mạch, 5 kho có mạch thì không có Fact ấy; thêm nữa Fact dùng chủ thể chip:X mà ERC không tra tiền tố đó | G28: không có cờ — sửa lỗi thuần
A29: 10 | B29: M3-03 | C29: 3. Mạch, ERC, HDL/FPGA | D29: P0 | E29: DEV-339 | F29: 8 phát hiện trên 5 mạch thật (6 nguon_khong_cap + 2 net_mot_chan), trong đó net clock I2C nối đúng một chân. SÁU trong tám là 'mô hình chưa khai' chứ không phải 'mạch sai'. robot-canbang: 107 Port lá, KHÔNG Port nào là power_out | G29: không có cờ — sửa lỗi thuần
A30: 11 | B30: M3-04 | C30: 3. Mạch, ERC, HDL/FPGA | D30: P0 | E30: DEV-340 | F30: 0 phát hiện trên 5 mạch thật — và đây là con số ĐÚNG (hai lỗi này catastrophic, không bo nào sống tới lúc lưu kho). Đã CẤY hai bộ cấp vào bản sao kho robot-canbang để chứng minh luật sống: nổ đúng 1 blocker trên net +5V thật | G30: không có cờ — sửa lỗi thuần
A31: 12 | B31: M3-07 | C31: 3. Mạch, ERC, HDL/FPGA | D31: P0 | E31: DEV-341 | F31: Fact tới được ERC: 5 → 17 (+12). Ba kho có Fact datasheet thì TOÀN BỘ mang chủ thể chip:, tức trước đó không một Fact nào tới được ERC. Độ phủ 5 mạch thật nay đọc được | G31: không có cờ — sửa lỗi thuần
... A34: 15 | B34: M3-13 | C34: 3. Mạch, ERC, HDL/FPGA | D34: P0 | E34: DEV-344 | F34: testbench Verilog THẬT của bài 3: tb_pcpi_dot4 1/1, tb_pcpi_mac 1/1, tb_pcpi_vmini không đo được (tb gọi bản bram HAI CỔNG đã bị bỏ 02/10) — mẫu số là TỆP, không phải phép phá | G34: không có cờ (công cụ mới core=False)
A35: 16 | B35: M3-18 | C35: 3. Mạch, ERC, HDL/FPGA | D35: P0 | E35: DEV-345 | F35: 6 cặp (mạng cổng, .cst) thật → 1 chỗ CHẶN: blinky của riscv-tn20k-b dựng bitstream 4,6 MB với chân đồng hồ do nextpnr tự chọn (rơi đúng chân 4 — bằng may). Cả 7 tệp .cst thật đọc hết, 0 lỗi cú pháp | G35: không có cờ (công cụ mới core=False)
A36: 17 | B36: M4-01 | C36: 4. Kiểm thử & chất lượng | D36: P0 | E36: DEV-346 | F36: 18 ca chạy trình biên dịch C thật: tệp test in số đo {"T1":300} với ngưỡng <=255 → EIDE phán 1 ca HỎNG. Chưa kho cũ nào có tiêu chí unit test để đo lại trên dữ liệu thật | G36: không có cờ (công cụ mới core=False)
A37: 18 | B37: M4-02 | C37: 4. Kiểm thử & chất lượng | D37: P0 | E37: DEV-347 | F37: 25 ca dựng đúng trạng thái thật (tệp test 3 ca, 1 ca đỏ, hiện vật dat=False) → fs.write còn 1 ca thì test.weakened=True. Và hàng rào cũ criteria.has_result chưa bao giờ nổ ngoài sim-01 | G37: SIM_RUNNER_GIOI_HAN — TẮT
A38: 19 | B38: M4-05 | C38: 4. Kiểm thử & chất lượng | D38: P1 | E38: DEV-348 | F38: du-lieu/rtos-sinhvien, chạy CẢ HAI hành vi: cũ so_thay=1, mới so_thay=0 — logo_ptit.c từ 'bộ kiểm ĐỎ' thành 'mọi đột biến đều làm hỏng biên dịch'. Một ô xanh giả, đã sửa | G38: không có cờ — sửa lỗi thuần
A39: 20 | B39: M4-19 | C39: 4. Kiểm thử & chất lượng | D39: P2 | E39: DEV-349 | F39: chạy TẠI CHỖ trên ba dự án firmware thật: kết luận giống hệt lượt đột biến tại chỗ của M4-05, và 50/50 tệp giữ nguyên cả sha256 lẫn mtime | G39: không có cờ — sửa lỗi thuần
A41: Việc còn MỞ (ngoài 86 việc chưa làm) | B41: Vì sao còn mở
A42: Bảy cờ mới đều còn TẮT | B42: GON_CONG_CU · TRUY_VET · REQ_PHU · REQ_CHAT_LUONG · KE_HOACH_CONG_KIEM · ERC_TU_DONG · SIM_RUNNER_GIOI_HAN. Cả bảy đổi thứ Agent nhìn thấy, đọc, hoặc LÀM ĐƯỢC mỗi lượt, nên chỉ bộ 76 ca chạy hai chế độ mới nói được chúng làm Agent khá hơn hay tệ hơn. Bộ ấy tốn tiền mô hình nên §3.0 bắt hỏi người dùng trước.
A43: kiem_cap_goi_tra() chưa thành hàng rào | B43: Soát được mọi phiên đã lưu, nhưng chưa hook nào gọi nó tự động — bắt được chuyện cũ, chưa chặn được chuyện mới.
A44: Luật ERC quá áp chưa nổ trên dữ liệu thật | B44: Đường dẫn đã thông ở M3-07, nhưng ba kho có Fact điện áp thì không có mô hình mạch, và ngược lại. Phải chờ một dự án có cả hai.
A45: Cột “Mã nguồn” của ma trận truy vết trống ở mọi dự án | B45: Nó đọc hien_thuc_req — trường vừa mới tồn tại, chưa tệp nào trên đĩa từng khai. Nên “chưa hiện thực” ở đó nghĩa là “chưa ai KHAI”, không phải “chưa ai viết”.
A46: Lỗi _go_dau trong src/eide/tools/design.py | B46: Viết .replace('d','d') nên 'ổn định' và 'ON DINH' không khớp nhau. Hàm ấy đang dùng cho một phép kiểm an toàn (người có thật sự chọn không). Tìm thấy ở M2-03, CHƯA sửa vì ngoài phạm vi — cần bộ ca kiểm riêng.
...

Sheet Tiến độ 09-10-2026 (chiều)
A1: TIẾN ĐỘ ĐỢT TỐI ƯU TÁC TỬ — chốt chiều 09/10/2026
A2: Mỗi dòng 'Xong' đều có: mục DEV-LOG tra lại được · số ca kiểm trước→sau · một con số đo trên dữ liệu thật · phần còn nợ. Cột chi tiết nằm ở sheet “Danh mục tối ưu”, cột T–Y.
A4: Tổng quan | B4: Số việc | C4: Ghi chú
A5: Xong (đã gộp vào main, đã đẩy) | B5: 21 | C5: 21 việc đầu của Giai đoạn 1, theo đúng thứ tự # của kế hoạch
A6: Đang làm (chưa commit) | B6: 0 | C6: không việc nào đang dở
A7: Chưa làm | B7: 85 | C7: 85 việc còn lại trong 106
A8: TỔNG | B8: 106
A10: Phép đo của cả đợt | B10: Trước (06/10) | C10: Sau (09/10) | D10: Ghi chú
A11: Ca đơn vị Python (pytest -q) | B11: 1 610 | C11: 1 862 | D11: +252 ca so với 06/10; không ca cũ nào đỏ ở bất kỳ bước nào
A12: Ca đơn vị giao diện (swift test) | B12: 43 | C12: 43 | D12: không nhiệm vụ nào đụng ui/ — kiểu khối A2.2 dùng “table”, Swift đã dựng được
A13: kiem_tai_lieu.py | B13: 0 chỗ lệch | C13: 0 chỗ lệch | D13: 0 chỗ LỆCH CHẮC CHẮN cả hai lượt. Hôm nay nó bắt đúng chuyện cần bắt: hai công cụ mới làm README lệch số công cụ 127 → 129, và số 'cần đọc lại' nhảy 11 → 15 → về 11 sau khi sửa
A14: thu_sch.py (cờ schematic bật) | B14: 63/63 | C14: 63/63 | D14: chạy ở M3-03 và M3-04, không tụt
A15: Mục DEV-LOG mới | B15: — | C15: DEV-330 → DEV-350 | D15: 21 mục, mỗi việc một mục
A16: Cờ tính năng mới | B16: 1 (schematic) | C16: 8 | D16: 7 cờ mới, TẤT CẢ mặc định TẮT. Cờ thứ 7 là SIM_RUNNER_GIOI_HAN (M4-02) — nó giới hạn fs.write của sim-runner trong sim/; hàng rào chính của M4-02 (POL-N6-sua-test) thì KHÔNG sau cờ
A17: Mã lỗi mới | B17: — | C17: E4031 · E4032 · E6012 · E4033 · E4024 | D17: M4-04, M4-05 và M4-19 không thêm mã nào; M4-02 dùng lại E5006. E4033 (M3-18), E4024 (M4-01). M4-01 còn DÙNG LẠI E4008/E4009/E4023 của sim.run — cùng một chuyện thì cùng một mã
A19: # | B19: Mã | C19: Mảng | D19: Ưu tiên | E19: DEV-LOG | F19: Ca kiểm | G19: Cờ mặc định
A20: 1 | B20: M1-01 | C20: 1. Lõi tác tử | D20: P0 | E20: DEV-330 | F20: 105/309 phiên thật có lịch sử tự mâu thuẫn — 255 chỗ (156 kết quả thứ hai cùng id, 74 message chen giữa, 24 kết quả lạc lượt, 1 lời gọi không kết quả) | G20: không có cờ — sửa lỗi thuần
A21: 2 | B21: M1-02 | C21: 1. Lõi tác tử | D21: P0 | E21: DEV-331 | F21: lược đồ công cụ thật: 25 869 token/lời gọi (trần tool_schema=4000 chưa dòng mã nào đọc). Cờ bật: 4 475 token, giảm 82,7 %; 73 → 18 công cụ | G21: GON_CONG_CU — TẮT
A22: 3 | B22: M1-03 | C22: 1. Lõi tác tử | D22: P0 | E22: DEV-332 | F22: 1 822 lời gọi của tác tử con trong 26 phiên thật, 0 lần qua lớp luật. Toàn công cụ đọc trừ một build.compile — lỗ hổng chưa bị bước vào, không phải được canh | G22: không có cờ — sửa lỗi thuần
A23: 4 | B23: M2-01 | C23: 2. Phân tích & thiết kế phần mềm | D23: P0 | E23: DEV-333 | F23: kịch bản 3 REQ + 3 phương án + 3 tiêu chí + 3 tệp: sửa MỘT REQ làm 9 hiện vật STALE → còn 3. Phép đo đầu ra 6→2 vì bị hàng rào E4020 chặn, đã sửa kịch bản đo | G23: TRUY_VET — TẮT (phần nền chạy cả khi tắt)
A24: 5 | B24: M2-02 | C24: 2. Phân tích & thiết kế phần mềm | D24: P0 | E24: DEV-334 | F24: 63 kho thật: 5/37 REQ có ít nhất một phép đo; 27 chưa có phương án nào nhận; 0 REQ đi hết chuỗi. Cột 'Mã nguồn' trống ở MỌI dự án vì hien_thuc_req vừa mới tồn tại | G24: REQ_PHU — TẮT (khối A2.2 trên tab không phụ thuộc cờ)
A25: 6 | B25: M2-03 | C25: 2. Phân tích & thiết kế phần mềm | D25: P0 | E25: DEV-335 | F25: 37 REQ thật: 25 sạch (67 %), 11 thiếu tiêu chí đo được, 2 có từ mơ hồ. Lần đo đầu ra 3 từ mơ hồ, một là kêu oan ('ít nhất 2 lần' là mức đo được) — đã vá | G25: REQ_CHAT_LUONG — TẮT (module yeu_cau.py luôn có)
A26: 7 | B26: M2-06 | C26: 2. Phân tích & thiết kế phần mềm | D26: P0 | E26: DEV-336 | F26: sổ cái thật: 26 lần đánh dấu 'xong' ngay sau một lần ghi mã, 19 lần (73 %) không có phép kiểm nào đạt ở giữa. Phép đo đầu ở mức dự án ra 0 — đúng nhưng đo sai câu hỏi | G26: KE_HOACH_CONG_KIEM — TẮT
