Workbook

Sheet Kiem tra
A1: Chỉ số | B1: Giá trị | C1: Ghi chú
A2: Tổng số yêu cầu (MDD-40) | B2: =COUNTA('Yeu cau'!A2:A283) | C2: Sheet Yeu cau
A3: Yêu cầu CHƯA được UI nào phủ | B3: =COUNTIF('Yeu cau'!F2:F283,"THIẾU") | C3: Phải = 0 (chiều Yêu cầu → UI)
A4: Tổng số vùng (cấp 1) | B4: =COUNTIF('UI 3 cap'!B2:B328,1)
A5: Tổng số khối (cấp 2) | B5: =COUNTIF('UI 3 cap'!B2:B328,2)
A6: Tổng số widget/hành động (cấp 3) | B6: =COUNTIF('UI 3 cap'!B2:B328,3)
A7: Widget cấp 3 CHƯA ánh xạ yêu cầu | B7: =COUNTIFS('UI 3 cap'!B2:B328,3,'UI 3 cap'!I2:I328,"THIẾU") | C7: Phải = 0 (chiều UI → Yêu cầu)
A8: Khối cấp 2 CHƯA ánh xạ | B8: =COUNTIFS('UI 3 cap'!B2:B328,2,'UI 3 cap'!I2:I328,"THIẾU") | C8: Phải = 0
A9: Vùng cấp 1 CHƯA ánh xạ | B9: =COUNTIFS('UI 3 cap'!B2:B328,1,'UI 3 cap'!I2:I328,"THIẾU") | C9: Phải = 0
A10: Tổng số cặp ánh xạ | B10: =COUNTA('Anh xa'!A2:A725)
A11: Cặp có mã yêu cầu không tồn tại | B11: =SUMPRODUCT((COUNTIF('Yeu cau'!$A$2:$A$283,'Anh xa'!D2:D725)=0)*1) | C11: Phải = 0
A12: KẾT LUẬN | B12: =IF(AND(B3=0,B7=0,B8=0,B9=0,B11=0),"ĐẠT — kín hai chiều","KHÔNG ĐẠT — xem ô đỏ")
A13: Yêu cầu theo trạng thái hiện thực: Đã làm | B13: =COUNTIF('Yeu cau'!G2:G283,"Đã làm") | C13: Cột vàng do người điền
A14: Yêu cầu theo trạng thái hiện thực: Đang làm | B14: =COUNTIF('Yeu cau'!G2:G283,"Đang làm")
A15: Yêu cầu theo trạng thái hiện thực: Chưa làm | B15: =COUNTIF('Yeu cau'!G2:G283,"Chưa làm")

Sheet Huong dan
A1: MA TRẬN ÁNH XẠ HAI CHIỀU — YÊU CẦU (EIDE-MDD-40 v3.0) ↔ GIAO DIỆN (EIDE_v3.0_UI_prototype.html)
A3: 1. Nguồn: cả HTML và Excel này được sinh từ CÙNG một mô hình (ui_model.py). Mã UI trong HTML (bật 'Chế độ truy vết') trùng với cột 'Mã UI' ở đây.
A4: 2. Cấp UI: Cấp 1 = Vùng (A0–A14: thanh trạng thái, Console, 10 tab, thẻ cổng, thiết lập, dự án) · Cấp 2 = Khối (Ax.y) · Cấp 3 = Widget/Hành động (Ax.y.z).
A5: 3. Sheet 'Yeu cau': 198 yêu cầu rút từ MDD-40 (nguyên tắc, bất biến, chặng, UC, HumanAct, UICommand, cổng, hiện vật, lớp giải thích, quy tắc trình bày, đồng bộ khi sửa, changeset, snapshot, tầng, luồng datasheet, bố cục, ngữ cảnh, bộ nhớ, sự cố, năng lực). Cột 'Số UI ánh xạ' là CÔNG THỨC đếm từ sheet 'Anh xa'; = 0 → THIẾU.
A6: 4. Sheet 'UI 3 cap': toàn bộ cây UI. Cột 'Số yêu cầu' là công thức; widget cấp 3 = 0 → THIẾU (khối cấp 2 và vùng cấp 1 được phủ qua widget con hoặc yêu cầu gán trực tiếp).
A7: 5. Sheet 'Anh xa' (dạng dài): mỗi dòng một cặp (UI, yêu cầu). Đây là bảng gốc cho hai chiều; sửa ở đây thì hai sheet kiểm tra tự cập nhật.
A8: 6. Sheet 'REQ -> UI' và 'UI -> REQ': bảng đọc nhanh, mỗi dòng một ID với danh sách ID phía kia (chuỗi do trình sinh ghép) + công thức đếm để đối chiếu.
A9: 7. Sheet 'Kiem tra': tổng hợp; ô 'KẾT LUẬN' phải là ĐẠT (0 yêu cầu chưa phủ, 0 widget chưa ánh xạ).
A10: 8. Chỉ điền cột nền vàng (Ghi chú rà soát, Trạng thái hiện thực) khi dùng để theo dõi hiện thực; các cột khác do trình sinh quản lý.
A12: Ngày sinh: 25/09/2026 · Nguồn yêu cầu: EIDE-MDD-40 v3.0 · Tác giả: Vũ Trí Công (Đề án ThS Kỹ thuật Điện tử — PTIT, GVHD TS. Nguyễn Trung Hiếu)

Sheet Anh xa
A1: Mã UI | B1: Tên UI | C1: Cấp | D1: Mã yêu cầu | E1: Nhóm yêu cầu | F1: Mô tả yêu cầu | G1: Nguồn § | H1: Ghi chú rà soát
A2: A0.1 | B2: Trạng thái dự án | C2: 2 | D2: LY-statusbar | E2: Bố cục | F2: Thanh trạng thái: dự án, nhánh, chip, Fact theo tầng, chặng, snapshot + khoảng cách, STALE | G2: MDD-40 E7
A3: A0.1 | B3: Trạng thái dự án | C3: 2 | D3: N3 | E3: Nguyên tắc | F3: Kiểm kê xác định — tình trạng dự án do mã dựng, hiển thị cho người | G3: MDD-40 A3
A4: A0.1.1 | B4: Tên dự án + nhánh hiện tại | C4: 3 | D4: LY-statusbar | E4: Bố cục | F4: Thanh trạng thái: dự án, nhánh, chip, Fact theo tầng, chặng, snapshot + khoảng cách, STALE | G4: MDD-40 E7
A5: A0.1.1 | B5: Tên dự án + nhánh hiện tại | C5: 3 | D5: CS-branch | E5: Changeset & rollback | F5: Rẽ nhánh phương án; so sánh; gộp | G5: MDD-40 E5
A6: A0.1.1 | B6: Tên dự án + nhánh hiện tại | C6: 3 | D6: UC17 | E6: Usecase | F6: Quản lý phiên/dự án | G6: Excel 76 TC
A7: A0.1.2 | B7: Chip đã ghim (ns.part@semver) + ISA | C7: 3 | D7: AR05 | E7: Hiện vật (E2) | F7: Hộ chiếu chip | G7: MDD-40 E2
A8: A0.1.2 | B8: Chip đã ghim (ns.part@semver) + ISA | C8: 3 | D8: DS6 | E8: Luồng datasheet | F8: Ghim hộ chiếu; đối chiếu ISA | G8: MDD-40 C3
A9: A0.1.3 | B9: Fact theo tầng (VÀNG/BẠC/NGƯỜI/ĐỒNG) | C9: 3 | D9: T-VANG | E9: Tầng dữ liệu | F9: Tầng VÀNG — nền vàng, khoá, mở trang nguồn | G9: MDD-40 C1
A10: A0.1.3 | B10: Fact theo tầng (VÀNG/BẠC/NGƯỜI/ĐỒNG) | C10: 3 | D10: T-BAC | E10: Tầng dữ liệu | F10: Tầng BẠC — nền xám, nút Xác nhận | G10: MDD-40 C1
A11: A0.1.3 | B11: Fact theo tầng (VÀNG/BẠC/NGƯỜI/ĐỒNG) | C11: 3 | D11: T-NGUOI | E11: Tầng dữ liệu | F11: Tầng NGƯỜI — 'anh cho, chưa có tài liệu', nút Tìm tài liệu | G11: MDD-40 C1
A12: A0.1.3 | B12: Fact theo tầng (VÀNG/BẠC/NGƯỜI/ĐỒNG) | C12: 3 | D12: T-DONG | E12: Tầng dữ liệu | F12: Tầng ĐỒNG — nghiêng, 'chưa kiểm chứng' | G12: MDD-40 C1
A13: A0.1.3 | B13: Fact theo tầng (VÀNG/BẠC/NGƯỜI/ĐỒNG) | C13: 3 | D13: N2 | E13: Nguyên tắc | F13: Bốn tầng tin cậy VÀNG/BẠC/NGƯỜI/ĐỒNG; ĐỒNG không là vế so sánh | G13: MDD-40 A3
... A725: A14.5.1 | B725: Sinh tài liệu thiết kế/hướng dẫn; đánh dấu phần lỗi thời sau khi sửa | C725: 3 | D725: TL-trace | E725: Năng lực chuyên môn | F725: Ma trận truy vết yêu cầu↔thiết kế↔mã↔test | G725: MDD-40 B3/UC

Sheet Yeu cau
A1: Mã yêu cầu | B1: Nhóm | C1: Mô tả | D1: Nguồn § | E1: Số UI ánh xạ (công thức) | F1: Trạng thái phủ | G1: Trạng thái hiện thực | H1: Ghi chú rà soát
A2: N1 | B2: Nguyên tắc | C2: Datasheet là nguồn sự thật — mọi con số truy vết tới tài liệu/trang | D2: MDD-40 A3 | E2: =COUNTIF('Anh xa'!$D$2:$D$725,A2) | F2: =IF(E2>0,"Đã phủ","THIẾU") | G2: Chưa làm
A3: N2 | B3: Nguyên tắc | C3: Bốn tầng tin cậy VÀNG/BẠC/NGƯỜI/ĐỒNG; ĐỒNG không là vế so sánh | D3: MDD-40 A3 | E3: =COUNTIF('Anh xa'!$D$2:$D$725,A3) | F3: =IF(E3>0,"Đã phủ","THIẾU") | G3: Chưa làm
A4: N3 | B4: Nguyên tắc | C4: Kiểm kê xác định — tình trạng dự án do mã dựng, hiển thị cho người | D4: MDD-40 A3 | E4: =COUNTIF('Anh xa'!$D$2:$D$725,A4) | F4: =IF(E4>0,"Đã phủ","THIẾU") | G4: Chưa làm
A5: N4 | B5: Nguyên tắc | C5: Hỏi một cụm, ≤ 2 lần/lượt, nói ra giả định | D5: MDD-40 A3 | E5: =COUNTIF('Anh xa'!$D$2:$D$725,A5) | F5: =IF(E5>0,"Đã phủ","THIẾU") | G5: Chưa làm
A6: N5 | B6: Nguyên tắc | C6: Cổng an toàn đứng trước phép đoán (S0, G-OPS never_auto) | D6: MDD-40 A3 | E6: =COUNTIF('Anh xa'!$D$2:$D$725,A6) | F6: =IF(E6>0,"Đã phủ","THIẾU") | G6: Chưa làm
A7: N6 | B7: Nguyên tắc | C7: Không đạt giả — tiêu chí của người; log rỗng ≠ đạt; phần chưa mô phỏng nói rõ | D7: MDD-40 A3 | E7: =COUNTIF('Anh xa'!$D$2:$D$725,A7) | F7: =IF(E7>0,"Đã phủ","THIẾU") | G7: Chưa làm
A8: N7 | B8: Nguyên tắc | C8: Chỉ thị cho tác tử ≠ yêu cầu sản phẩm; rủi ro tách riêng | D8: MDD-40 A3 | E8: =COUNTIF('Anh xa'!$D$2:$D$725,A8) | F8: =IF(E8>0,"Đã phủ","THIẾU") | G8: Chưa làm
A9: N8 | B9: Nguyên tắc | C9: Mọi thứ tác tử làm ra có dạng người hiểu được (lớp giải thích 6 trường) | D9: MDD-40 A3 | E9: =COUNTIF('Anh xa'!$D$2:$D$725,A9) | F9: =IF(E9>0,"Đã phủ","THIẾU") | G9: Chưa làm
A10: N9 | B10: Nguyên tắc | C10: Mọi thay đổi là changeset hoàn tác được; sửa của người được tác tử biết; snapshot bất biến | D10: MDD-40 A3 | E10: =COUNTIF('Anh xa'!$D$2:$D$725,A10) | F10: =IF(E10>0,"Đã phủ","THIẾU") | G10: Chưa làm
A11: I1 | B11: Bất biến giao thức | C11: Một cửa vào: console.act / HumanAct | D11: MDD-40 D1 | E11: =COUNTIF('Anh xa'!$D$2:$D$725,A11) | F11: =IF(E11>0,"Đã phủ","THIẾU") | G11: Chưa làm
A12: I2 | B12: Bất biến giao thức | C12: Một dòng hội thoại: mọi HumanAct và lời tác tử trong transcript | D12: MDD-40 D1 | E12: =COUNTIF('Anh xa'!$D$2:$D$725,A12) | F12: =IF(E12>0,"Đã phủ","THIẾU") | G12: Chưa làm
A13: I3 | B13: Bất biến giao thức | C13: Giao diện không quyết — chỉ render SurfaceModel/Card | D13: MDD-40 D1 | E13: =COUNTIF('Anh xa'!$D$2:$D$725,A13) | F13: =IF(E13>0,"Đã phủ","THIẾU") | G13: Chưa làm
... A283: HIER-18 | B283: Cây khối phân cấp (HIER-45) | C283: Hồi quy toàn bộ giống 100 % sau migration | D283: EIDE-HIER-45 | E283: =COUNTIF('Anh xa'!$D$2:$D$725,A283) | F283: =IF(E283>0,"Đã phủ","THIẾU") | G283: Chưa làm

Sheet UI 3 cap
A1: Mã UI | B1: Cấp | C1: Vùng (cấp 1) | D1: Khối (cấp 2) | E1: Widget / hành động (cấp 3) | F1: Loại | G1: Hiện vật | H1: Số yêu cầu (công thức) | I1: Trạng thái ánh xạ | J1: Trạng thái hiện thực | K1: Ghi chú rà soát
A2: A0 | B2: 1 | C2: Thanh trạng thái | F2: bar | H2: =COUNTIF('Anh xa'!$A$2:$A$725,"A0.*") | I2: =IF(H2>0,"Đã ánh xạ","THIẾU") | J2: Chưa làm
A3: A0.1 | B3: 2 | C3: Thanh trạng thái | D3: Trạng thái dự án | F3: khối | H3: =COUNTIF('Anh xa'!$A$2:$A$725,"A0.1")+COUNTIF('Anh xa'!$A$2:$A$725,"A0.1.*") | I3: =IF(H3>0,"Đã ánh xạ","THIẾU") | J3: Chưa làm
A4: A0.1.1 | B4: 3 | C4: Thanh trạng thái | D4: Trạng thái dự án | E4: Tên dự án + nhánh hiện tại | F4: display | H4: =COUNTIF('Anh xa'!$A$2:$A$725,A4) | I4: =IF(H4>0,"Đã ánh xạ","THIẾU") | J4: Chưa làm
A5: A0.1.2 | B5: 3 | C5: Thanh trạng thái | D5: Trạng thái dự án | E5: Chip đã ghim (ns.part@semver) + ISA | F5: display | H5: =COUNTIF('Anh xa'!$A$2:$A$725,A5) | I5: =IF(H5>0,"Đã ánh xạ","THIẾU") | J5: Chưa làm
A6: A0.1.3 | B6: 3 | C6: Thanh trạng thái | D6: Trạng thái dự án | E6: Fact theo tầng (VÀNG/BẠC/NGƯỜI/ĐỒNG) | F6: display | H6: =COUNTIF('Anh xa'!$A$2:$A$725,A6) | I6: =IF(H6>0,"Đã ánh xạ","THIẾU") | J6: Chưa làm
A7: A0.1.4 | B7: 3 | C7: Thanh trạng thái | D7: Trạng thái dự án | E7: Chặng hiện tại C1–C7 | F7: display | H7: =COUNTIF('Anh xa'!$A$2:$A$725,A7) | I7: =IF(H7>0,"Đã ánh xạ","THIẾU") | J7: Chưa làm
A8: A0.1.5 | B8: 3 | C8: Thanh trạng thái | D8: Trạng thái dự án | E8: Snapshot gần nhất + khoảng cách (changeset) | F8: display | H8: =COUNTIF('Anh xa'!$A$2:$A$725,A8) | I8: =IF(H8>0,"Đã ánh xạ","THIẾU") | J8: Chưa làm
A9: A0.1.6 | B9: 3 | C9: Thanh trạng thái | D9: Trạng thái dự án | E9: Số hiện vật STALE (bấm → Lịch sử) | F9: nav | H9: =COUNTIF('Anh xa'!$A$2:$A$725,A9) | I9: =IF(H9>0,"Đã ánh xạ","THIẾU") | J9: Chưa làm
A10: A0.1.7 | B10: 3 | C10: Thanh trạng thái | D10: Trạng thái dự án | E10: Mức tự chủ hiện tại (A0–A4) + mô hình | F10: display | H10: =COUNTIF('Anh xa'!$A$2:$A$725,A10) | I10: =IF(H10>0,"Đã ánh xạ","THIẾU") | J10: Chưa làm
A11: A0.1.8 | B11: 3 | C11: Thanh trạng thái | D11: Trạng thái dự án | E11: Ngân sách lượt: tool/40 · giây/300 · ngữ cảnh % | F11: display | H11: =COUNTIF('Anh xa'!$A$2:$A$725,A11) | I11: =IF(H11>0,"Đã ánh xạ","THIẾU") | J11: Chưa làm
A12: A0.1.9 | B12: 3 | C12: Thanh trạng thái | D12: Trạng thái dự án | E12: Trạng thái kết nối lõi/mạng | F12: display | H12: =COUNTIF('Anh xa'!$A$2:$A$725,A12) | I12: =IF(H12>0,"Đã ánh xạ","THIẾU") | J12: Chưa làm
A13: A1 | B13: 1 | C13: Bàn giao tiếp (Console) | F13: panel | H13: =COUNTIF('Anh xa'!$A$2:$A$725,"A1.*") | I13: =IF(H13>0,"Đã ánh xạ","THIẾU") | J13: Chưa làm
A14: A1.1 | B14: 2 | C14: Bàn giao tiếp (Console) | D14: Dòng hội thoại (transcript) | F14: khối | H14: =COUNTIF('Anh xa'!$A$2:$A$725,"A1.1")+COUNTIF('Anh xa'!$A$2:$A$725,"A1.1.*") | I14: =IF(H14>0,"Đã ánh xạ","THIẾU") | J14: Chưa làm
A15: A1.1.1 | B15: 3 | C15: Bàn giao tiếp (Console) | D15: Dòng hội thoại (transcript) | E15: Dòng [Tác tử] (stream, markdown, liên kết mở tab) | F15: display | H15: =COUNTIF('Anh xa'!$A$2:$A$725,A15) | I15: =IF(H15>0,"Đã ánh xạ","THIẾU") | J15: Chưa làm
A16: A1.1.2 | B16: 3 | C16: Bàn giao tiếp (Console) | D16: Dòng hội thoại (transcript) | E16: Dòng [Bạn] cho MỌI HumanAct (kể cả thao tác trên tab) | F16: display | H16: =COUNTIF('Anh xa'!$A$2:$A$725,A16) | I16: =IF(H16>0,"Đã ánh xạ","THIẾU") | J16: Chưa làm
A17: A1.1.3 | B17: 3 | C17: Bàn giao tiếp (Console) | D17: Dòng hội thoại (transcript) | E17: Dòng [Hệ thống] sự cố/thông báo | F17: display | H17: =COUNTIF('Anh xa'!$A$2:$A$725,A17) | I17: =IF(H17>0,"Đã ánh xạ","THIẾU") | J17: Chưa làm
A18: A1.1.4 | B18: 3 | C18: Bàn giao tiếp (Console) | D18: Dòng hội thoại (transcript) | E18: Báo cáo lượt (đã làm / bỏ / giả định / hoàn tác tới đâu / chi phí) | F18: display | H18: =COUNTIF('Anh xa'!$A$2:$A$725,A18) | I18: =IF(H18>0,"Đã ánh xạ","THIẾU") | J18: Chưa làm
A19: A1.1.5 | B19: 3 | C19: Bàn giao tiếp (Console) | D19: Dòng hội thoại (transcript) | E19: Phát lại (replay) transcript từ sổ cái | F19: action | H19: =COUNTIF('Anh xa'!$A$2:$A$725,A19) | I19: =IF(H19>0,"Đã ánh xạ","THIẾU") | J19: Chưa làm
A20: A1.2 | B20: 2 | C20: Bàn giao tiếp (Console) | D20: Ô nhập | F20: khối | H20: =COUNTIF('Anh xa'!$A$2:$A$725,"A1.2")+COUNTIF('Anh xa'!$A$2:$A$725,"A1.2.*") | I20: =IF(H20>0,"Đã ánh xạ","THIẾU") | J20: Chưa làm
A21: A1.2.1 | B21: 3 | C21: Bàn giao tiếp (Console) | D21: Ô nhập | E21: Gõ tự do (say) + Enter gửi | F21: edit | H21: =COUNTIF('Anh xa'!$A$2:$A$725,A21) | I21: =IF(H21>0,"Đã ánh xạ","THIẾU") | J21: Chưa làm
A22: A1.2.2 | B22: 3 | C22: Bàn giao tiếp (Console) | D22: Ô nhập | E22: Đính kèm tệp (upload) | F22: edit | H22: =COUNTIF('Anh xa'!$A$2:$A$725,A22) | I22: =IF(H22>0,"Đã ánh xạ","THIẾU") | J22: Chưa làm
A23: A1.2.3 | B23: 3 | C23: Bàn giao tiếp (Console) | D23: Ô nhập | E23: Lệnh nhanh: /dung /tiep-tuc /hoan-tac /snapshot /nhanh | F23: action | H23: =COUNTIF('Anh xa'!$A$2:$A$725,A23) | I23: =IF(H23>0,"Đã ánh xạ","THIẾU") | J23: Chưa làm
A24: A1.2.4 | B24: 3 | C24: Bàn giao tiếp (Console) | D24: Ô nhập | E24: Gợi ý điền sẵn từ ngữ cảnh (chip, tệp, run vừa nhắc) | F24: display | H24: =COUNTIF('Anh xa'!$A$2:$A$725,A24) | I24: =IF(H24>0,"Đã ánh xạ","THIẾU") | J24: Chưa làm
A25: A1.3 | B25: 2 | C25: Bàn giao tiếp (Console) | D25: Thẻ đang chờ (Card) | F25: khối | H25: =COUNTIF('Anh xa'!$A$2:$A$725,"A1.3")+COUNTIF('Anh xa'!$A$2:$A$725,"A1.3.*") | I25: =IF(H25>0,"Đã ánh xạ","THIẾU") | J25: Chưa làm
A26: A1.3.1 | B26: 3 | C26: Bàn giao tiếp (Console) | D26: Thẻ đang chờ (Card) | E26: Thẻ làm rõ (clarify) nhiều mục, mục bắt buộc/tuỳ chọn có default | F26: edit | H26: =COUNTIF('Anh xa'!$A$2:$A$725,A26) | I26: =IF(H26>0,"Đã ánh xạ","THIẾU") | J26: Chưa làm
A27: A1.3.2 | B27: 3 | C27: Bàn giao tiếp (Console) | D27: Thẻ đang chờ (Card) | E27: Thẻ đề nghị (proposal) 3 lựa chọn — ví dụ datasheet chip | F27: edit | H27: =COUNTIF('Anh xa'!$A$2:$A$725,A27) | I27: =IF(H27>0,"Đã ánh xạ","THIẾU") | J27: Chưa làm
A28: A1.3.3 | B28: 3 | C28: Bàn giao tiếp (Console) | D28: Thẻ đang chờ (Card) | E28: Thẻ kế hoạch (plan) có checkbox bước + chi phí + giả định | F28: edit | H28: =COUNTIF('Anh xa'!$A$2:$A$725,A28) | I28: =IF(H28>0,"Đã ánh xạ","THIẾU") | J28: Chưa làm
A29: A1.3.4 | B29: 3 | C29: Bàn giao tiếp (Console) | D29: Thẻ đang chờ (Card) | E29: Thẻ tiêu chí (criteria) form assert | F29: edit | H29: =COUNTIF('Anh xa'!$A$2:$A$725,A29) | I29: =IF(H29>0,"Đã ánh xạ","THIẾU") | J29: Chưa làm
A30: A1.3.5 | B30: 3 | C30: Bàn giao tiếp (Console) | D30: Thẻ đang chờ (Card) | E30: Thẻ báo cáo (report) + Mở tab / Hoàn tác | F30: display | H30: =COUNTIF('Anh xa'!$A$2:$A$725,A30) | I30: =IF(H30>0,"Đã ánh xạ","THIẾU") | J30: Chưa làm
A31: A1.3.6 | B31: 3 | C31: Bàn giao tiếp (Console) | D31: Thẻ đang chờ (Card) | E31: Thẻ đã đóng/hết hạn (mờ, giữ nội dung) | F31: display | H31: =COUNTIF('Anh xa'!$A$2:$A$725,A31) | I31: =IF(H31>0,"Đã ánh xạ","THIẾU") | J31: Chưa làm
A32: A1.4 | B32: 2 | C32: Bàn giao tiếp (Console) | D32: Thẻ Run (lượt đang chạy) | F32: khối | H32: =COUNTIF('Anh xa'!$A$2:$A$725,"A1.4")+COUNTIF('Anh xa'!$A$2:$A$725,"A1.4.*") | I32: =IF(H32>0,"Đã ánh xạ","THIẾU") | J32: Chưa làm
A33: A1.4.1 | B33: 3 | C33: Bàn giao tiếp (Console) | D33: Thẻ Run (lượt đang chạy) | E33: Tiến trình theo bước/tool (đang chạy, xong, bỏ, chờ cổng) | F33: display | H33: =COUNTIF('Anh xa'!$A$2:$A$725,A33) | I33: =IF(H33>0,"Đã ánh xạ","THIẾU") | J33: Chưa làm
A34: A1.4.2 | B34: 3 | C34: Bàn giao tiếp (Console) | D34: Thẻ Run (lượt đang chạy) | E34: Subagent đang chạy (tên, tool được phép, trạng thái) | F34: display | H34: =COUNTIF('Anh xa'!$A$2:$A$725,A34) | I34: =IF(H34>0,"Đã ánh xạ","THIẾU") | J34: Chưa làm
A35: A1.4.3 | B35: 3 | C35: Bàn giao tiếp (Console) | D35: Thẻ Run (lượt đang chạy) | E35: Nút Dừng khẩn | F35: action | H35: =COUNTIF('Anh xa'!$A$2:$A$725,A35) | I35: =IF(H35>0,"Đã ánh xạ","THIẾU") | J35: Chưa làm
A36: A1.4.4 | B36: 3 | C36: Bàn giao tiếp (Console) | D36: Thẻ Run (lượt đang chạy) | E36: Nút Hoàn tác lượt (30 s không cần thẻ) | F36: action | H36: =COUNTIF('Anh xa'!$A$2:$A$725,A36) | I36: =IF(H36>0,"Đã ánh xạ","THIẾU") | J36: Chưa làm
A37: A1.4.5 | B37: 3 | C37: Bàn giao tiếp (Console) | D37: Thẻ Run (lượt đang chạy) | E37: Nút Ghi bản ưng ý | F37: action | H37: =COUNTIF('Anh xa'!$A$2:$A$725,A37) | I37: =IF(H37>0,"Đã ánh xạ","THIẾU") | J37: Chưa làm
A38: A1.4.6 | B38: 3 | C38: Bàn giao tiếp (Console) | D38: Thẻ Run (lượt đang chạy) | E38: Giả định đang dùng của lượt | F38: display | H38: =COUNTIF('Anh xa'!$A$2:$A$725,A38) | I38: =IF(H38>0,"Đã ánh xạ","THIẾU") | J38: Chưa làm
A39: A1.4.7 | B39: 3 | C39: Bàn giao tiếp (Console) | D39: Thẻ Run (lượt đang chạy) | E39: Chi phí token/giây đến hiện tại | F39: display | H39: =COUNTIF('Anh xa'!$A$2:$A$725,A39) | I39: =IF(H39>0,"Đã ánh xạ","THIẾU") | J39: Chưa làm
A40: A1.4.8 | B40: 3 | C40: Bàn giao tiếp (Console) | D40: Thẻ Run (lượt đang chạy) | E40: Nút Tiếp tục (sau sự cố/dừng) | F40: action | H40: =COUNTIF('Anh xa'!$A$2:$A$725,A40) | I40: =IF(H40>0,"Đã ánh xạ","THIẾU") | J40: Chưa làm
...

Sheet REQ -> UI
A1: Mã yêu cầu | B1: Nhóm | C1: Mô tả | D1: Danh sách mã UI (ghép) | E1: Số UI (ghép) | F1: Số UI (công thức từ Anh xa) | G1: Khớp?
A2: N1 | B2: Nguyên tắc | C2: Datasheet là nguồn sự thật — mọi con số truy vết tới tài liệu/trang | D2: A2.5, A2.5.1, A3.4.1, A3.4.2, A3.5.1, A4.2, A5.2.2, A5.9.3, A7.1.1, A7.2.1, A9.1.1, A9.4.1, A9.7.1 | E2: 13 | F2: =SUMPRODUCT(('Anh xa'!$D$2:$D$725=A2)*1) | G2: =IF(AND(F2>0,F2=E2),"✓","THIẾU")
A3: N2 | B3: Nguyên tắc | C3: Bốn tầng tin cậy VÀNG/BẠC/NGƯỜI/ĐỒNG; ĐỒNG không là vế so sánh | D3: A0.1.3, A2.3.2, A4.2, A4.4, A4.4.1, A5.9.7 | E3: 6 | F3: =SUMPRODUCT(('Anh xa'!$D$2:$D$725=A3)*1) | G3: =IF(AND(F3>0,F3=E3),"✓","THIẾU")
A4: N3 | B4: Nguyên tắc | C4: Kiểm kê xác định — tình trạng dự án do mã dựng, hiển thị cho người | D4: A0.1, A14.1.1, A14.3.1, A6.1.1 | E4: 4 | F4: =SUMPRODUCT(('Anh xa'!$D$2:$D$725=A4)*1) | G4: =IF(AND(F4>0,F4=E4),"✓","THIẾU")
A5: N4 | B5: Nguyên tắc | C5: Hỏi một cụm, ≤ 2 lần/lượt, nói ra giả định | D5: A1.1.4, A1.2.4, A1.3.1, A1.4.6, A2.5.2, A9.7.1 | E5: 6 | F5: =SUMPRODUCT(('Anh xa'!$D$2:$D$725=A5)*1) | G5: =IF(AND(F5>0,F5=E5),"✓","THIẾU")
A6: N5 | B6: Nguyên tắc | C6: Cổng an toàn đứng trước phép đoán (S0, G-OPS never_auto) | D6: A1.4.3, A12.1.1, A9.5, A9.5.1, A9.6.1 | E6: 5 | F6: =SUMPRODUCT(('Anh xa'!$D$2:$D$725=A6)*1) | G6: =IF(AND(F6>0,F6=E6),"✓","THIẾU")
A7: N6 | B7: Nguyên tắc | C7: Không đạt giả — tiêu chí của người; log rỗng ≠ đạt; phần chưa mô phỏng nói rõ | D7: A1.3.4, A5.5.2, A8.1, A8.1.3, A8.2.1, A8.2.4, A8.2.6 | E7: 7 | F7: =SUMPRODUCT(('Anh xa'!$D$2:$D$725=A7)*1) | G7: =IF(AND(F7>0,F7=E7),"✓","THIẾU")
A8: N7 | B8: Nguyên tắc | C8: Chỉ thị cho tác tử ≠ yêu cầu sản phẩm; rủi ro tách riêng | D8: A2.1, A2.1.2, A2.2, A2.2.1 | E8: 4 | F8: =SUMPRODUCT(('Anh xa'!$D$2:$D$725=A8)*1) | G8: =IF(AND(F8>0,F8=E8),"✓","THIẾU")
A9: N8 | B9: Nguyên tắc | C9: Mọi thứ tác tử làm ra có dạng người hiểu được (lớp giải thích 6 trường) | D9: A13.5.2, A2.1.1, A5.9.9 | E9: 3 | F9: =SUMPRODUCT(('Anh xa'!$D$2:$D$725=A9)*1) | G9: =IF(AND(F9>0,F9=E9),"✓","THIẾU")
A10: N9 | B10: Nguyên tắc | C10: Mọi thay đổi là changeset hoàn tác được; sửa của người được tác tử biết; snapshot bất biến | D10: A14.2.2, A2.1.8, A9.5.2 | E10: 3 | F10: =SUMPRODUCT(('Anh xa'!$D$2:$D$725=A10)*1) | G10: =IF(AND(F10>0,F10=E10),"✓","THIẾU")
A11: I1 | B11: Bất biến giao thức | C11: Một cửa vào: console.act / HumanAct | D11: A1.1.2, A1.2.1 | E11: 2 | F11: =SUMPRODUCT(('Anh xa'!$D$2:$D$725=A11)*1) | G11: =IF(AND(F11>0,F11=E11),"✓","THIẾU")
A12: I2 | B12: Bất biến giao thức | C12: Một dòng hội thoại: mọi HumanAct và lời tác tử trong transcript | D12: A1.1, A1.1.2, A1.1.5, A10.1, A10.1.1 | E12: 5 | F12: =SUMPRODUCT(('Anh xa'!$D$2:$D$725=A12)*1) | G12: =IF(AND(F12>0,F12=E12),"✓","THIẾU")
A13: I3 | B13: Bất biến giao thức | C13: Giao diện không quyết — chỉ render SurfaceModel/Card | D13: A13.5, A13.5.1, A13.5.2 | E13: 3 | F13: =SUMPRODUCT(('Anh xa'!$D$2:$D$725=A13)*1) | G13: =IF(AND(F13>0,F13=E13),"✓","THIẾU")
... A283: HIER-18 | B283: Cây khối phân cấp (HIER-45) | C283: Hồi quy toàn bộ giống 100 % sau migration | D283: A5.9.12 | E283: 1 | F283: =SUMPRODUCT(('Anh xa'!$D$2:$D$725=A283)*1) | G283: =IF(AND(F283>0,F283=E283),"✓","THIẾU")

Sheet UI -> REQ
A1: Mã UI | B1: Cấp | C1: Tên UI | D1: Danh sách mã yêu cầu (ghép) | E1: Số yêu cầu (ghép) | F1: Số yêu cầu (công thức từ Anh xa) | G1: Khớp?
A2: A0.1 | B2: 2 | C2: Trạng thái dự án | D2: LY-statusbar, N3 | E2: 2 | F2: =SUMPRODUCT(('Anh xa'!$A$2:$A$725=A2)*1) | G2: =IF(F2>0,"✓","THIẾU")
A3: A0.1.1 | B3: 3 | C3: Tên dự án + nhánh hiện tại | D3: CS-branch, LY-statusbar, UC17 | E3: 3 | F3: =SUMPRODUCT(('Anh xa'!$A$2:$A$725=A3)*1) | G3: =IF(F3>0,"✓","THIẾU")
A4: A0.1.2 | B4: 3 | C4: Chip đã ghim (ns.part@semver) + ISA | D4: AR05, DS6 | E4: 2 | F4: =SUMPRODUCT(('Anh xa'!$A$2:$A$725=A4)*1) | G4: =IF(F4>0,"✓","THIẾU")
A5: A0.1.3 | B5: 3 | C5: Fact theo tầng (VÀNG/BẠC/NGƯỜI/ĐỒNG) | D5: N2, T-BAC, T-DONG, T-NGUOI, T-VANG | E5: 5 | F5: =SUMPRODUCT(('Anh xa'!$A$2:$A$725=A5)*1) | G5: =IF(F5>0,"✓","THIẾU")
A6: A0.1.4 | B6: 3 | C6: Chặng hiện tại C1–C7 | D6: C1, C2, C3, C4, C5, C6, C7, CX-inventory | E6: 8 | F6: =SUMPRODUCT(('Anh xa'!$A$2:$A$725=A6)*1) | G6: =IF(F6>0,"✓","THIẾU")
A7: A0.1.5 | B7: 3 | C7: Snapshot gần nhất + khoảng cách (changeset) | D7: LY-statusbar, SN-resume-info | E7: 2 | F7: =SUMPRODUCT(('Anh xa'!$A$2:$A$725=A7)*1) | G7: =IF(F7>0,"✓","THIẾU")
A8: A0.1.6 | B8: 3 | C8: Số hiện vật STALE (bấm → Lịch sử) | D8: CS-stale, PR3 | E8: 2 | F8: =SUMPRODUCT(('Anh xa'!$A$2:$A$725=A8)*1) | G8: =IF(F8>0,"✓","THIẾU")
A9: A0.1.7 | B9: 3 | C9: Mức tự chủ hiện tại (A0–A4) + mô hình | D9: MM-autonomy, MM-model | E9: 2 | F9: =SUMPRODUCT(('Anh xa'!$A$2:$A$725=A9)*1) | G9: =IF(F9>0,"✓","THIẾU")
A10: A0.1.8 | B10: 3 | C10: Ngân sách lượt: tool/40 · giây/300 · ngữ cảnh % | D10: CX-budget, IN-timeout | E10: 2 | F10: =SUMPRODUCT(('Anh xa'!$A$2:$A$725=A10)*1) | G10: =IF(F10>0,"✓","THIẾU")
A11: A0.1.9 | B11: 3 | C11: Trạng thái kết nối lõi/mạng | D11: I5, IN-network | E11: 2 | F11: =SUMPRODUCT(('Anh xa'!$A$2:$A$725=A11)*1) | G11: =IF(F11>0,"✓","THIẾU")
A12: A1.1 | B12: 2 | C12: Dòng hội thoại (transcript) | D12: I2, UI-console.post, UI-console.stream | E12: 3 | F12: =SUMPRODUCT(('Anh xa'!$A$2:$A$725=A12)*1) | G12: =IF(F12>0,"✓","THIẾU")
A13: A1.1.1 | B13: 3 | C13: Dòng [Tác tử] (stream, markdown, liên kết mở tab) | D13: PR2, UI-console.post, UI-console.stream | E13: 3 | F13: =SUMPRODUCT(('Anh xa'!$A$2:$A$725=A13)*1) | G13: =IF(F13>0,"✓","THIẾU")
... A313: A14.5.1 | B313: 3 | C313: Sinh tài liệu thiết kế/hướng dẫn; đánh dấu phần lỗi thời sau khi sửa | D313: CS-stale, TL-trace, UC16 | E313: 3 | F313: =SUMPRODUCT(('Anh xa'!$A$2:$A$725=A313)*1) | G313: =IF(F313>0,"✓","THIẾU")

Sheet Theo nhom
A1: Nhóm yêu cầu | B1: Số yêu cầu | C1: Số yêu cầu đã phủ | D1: Số cặp ánh xạ
A2: Nguyên tắc | B2: =COUNTIF('Yeu cau'!B2:B283,A2) | C2: =COUNTIFS('Yeu cau'!B2:B283,A2,'Yeu cau'!F2:F283,"Đã phủ") | D2: =COUNTIF('Anh xa'!E2:E725,A2)
A3: Bất biến giao thức | B3: =COUNTIF('Yeu cau'!B2:B283,A3) | C3: =COUNTIFS('Yeu cau'!B2:B283,A3,'Yeu cau'!F2:F283,"Đã phủ") | D3: =COUNTIF('Anh xa'!E2:E725,A3)
A4: Chặng | B4: =COUNTIF('Yeu cau'!B2:B283,A4) | C4: =COUNTIFS('Yeu cau'!B2:B283,A4,'Yeu cau'!F2:F283,"Đã phủ") | D4: =COUNTIF('Anh xa'!E2:E725,A4)
A5: Usecase | B5: =COUNTIF('Yeu cau'!B2:B283,A5) | C5: =COUNTIFS('Yeu cau'!B2:B283,A5,'Yeu cau'!F2:F283,"Đã phủ") | D5: =COUNTIF('Anh xa'!E2:E725,A5)
A6: HumanAct | B6: =COUNTIF('Yeu cau'!B2:B283,A6) | C6: =COUNTIFS('Yeu cau'!B2:B283,A6,'Yeu cau'!F2:F283,"Đã phủ") | D6: =COUNTIF('Anh xa'!E2:E725,A6)
A7: UICommand | B7: =COUNTIF('Yeu cau'!B2:B283,A7) | C7: =COUNTIFS('Yeu cau'!B2:B283,A7,'Yeu cau'!F2:F283,"Đã phủ") | D7: =COUNTIF('Anh xa'!E2:E725,A7)
A8: Cổng | B8: =COUNTIF('Yeu cau'!B2:B283,A8) | C8: =COUNTIFS('Yeu cau'!B2:B283,A8,'Yeu cau'!F2:F283,"Đã phủ") | D8: =COUNTIF('Anh xa'!E2:E725,A8)
A9: Hiện vật (E2) | B9: =COUNTIF('Yeu cau'!B2:B283,A9) | C9: =COUNTIFS('Yeu cau'!B2:B283,A9,'Yeu cau'!F2:F283,"Đã phủ") | D9: =COUNTIF('Anh xa'!E2:E725,A9)
A10: Lớp giải thích | B10: =COUNTIF('Yeu cau'!B2:B283,A10) | C10: =COUNTIFS('Yeu cau'!B2:B283,A10,'Yeu cau'!F2:F283,"Đã phủ") | D10: =COUNTIF('Anh xa'!E2:E725,A10)
A11: Quy tắc trình bày | B11: =COUNTIF('Yeu cau'!B2:B283,A11) | C11: =COUNTIFS('Yeu cau'!B2:B283,A11,'Yeu cau'!F2:F283,"Đã phủ") | D11: =COUNTIF('Anh xa'!E2:E725,A11)
A12: Đồng bộ khi người sửa | B12: =COUNTIF('Yeu cau'!B2:B283,A12) | C12: =COUNTIFS('Yeu cau'!B2:B283,A12,'Yeu cau'!F2:F283,"Đã phủ") | D12: =COUNTIF('Anh xa'!E2:E725,A12)
A13: Loại sửa của người | B13: =COUNTIF('Yeu cau'!B2:B283,A13) | C13: =COUNTIFS('Yeu cau'!B2:B283,A13,'Yeu cau'!F2:F283,"Đã phủ") | D13: =COUNTIF('Anh xa'!E2:E725,A13)
A14: Changeset & rollback | B14: =COUNTIF('Yeu cau'!B2:B283,A14) | C14: =COUNTIFS('Yeu cau'!B2:B283,A14,'Yeu cau'!F2:F283,"Đã phủ") | D14: =COUNTIF('Anh xa'!E2:E725,A14)
A15: Snapshot | B15: =COUNTIF('Yeu cau'!B2:B283,A15) | C15: =COUNTIFS('Yeu cau'!B2:B283,A15,'Yeu cau'!F2:F283,"Đã phủ") | D15: =COUNTIF('Anh xa'!E2:E725,A15)
A16: Tầng dữ liệu | B16: =COUNTIF('Yeu cau'!B2:B283,A16) | C16: =COUNTIFS('Yeu cau'!B2:B283,A16,'Yeu cau'!F2:F283,"Đã phủ") | D16: =COUNTIF('Anh xa'!E2:E725,A16)
A17: Luồng datasheet | B17: =COUNTIF('Yeu cau'!B2:B283,A17) | C17: =COUNTIFS('Yeu cau'!B2:B283,A17,'Yeu cau'!F2:F283,"Đã phủ") | D17: =COUNTIF('Anh xa'!E2:E725,A17)
A18: Bố cục | B18: =COUNTIF('Yeu cau'!B2:B283,A18) | C18: =COUNTIFS('Yeu cau'!B2:B283,A18,'Yeu cau'!F2:F283,"Đã phủ") | D18: =COUNTIF('Anh xa'!E2:E725,A18)
A19: Ngữ cảnh tác tử | B19: =COUNTIF('Yeu cau'!B2:B283,A19) | C19: =COUNTIFS('Yeu cau'!B2:B283,A19,'Yeu cau'!F2:F283,"Đã phủ") | D19: =COUNTIF('Anh xa'!E2:E725,A19)
A20: Bộ nhớ người dùng | B20: =COUNTIF('Yeu cau'!B2:B283,A20) | C20: =COUNTIFS('Yeu cau'!B2:B283,A20,'Yeu cau'!F2:F283,"Đã phủ") | D20: =COUNTIF('Anh xa'!E2:E725,A20)
A21: Sự cố (UC19) | B21: =COUNTIF('Yeu cau'!B2:B283,A21) | C21: =COUNTIFS('Yeu cau'!B2:B283,A21,'Yeu cau'!F2:F283,"Đã phủ") | D21: =COUNTIF('Anh xa'!E2:E725,A21)
A22: Năng lực chuyên môn | B22: =COUNTIF('Yeu cau'!B2:B283,A22) | C22: =COUNTIFS('Yeu cau'!B2:B283,A22,'Yeu cau'!F2:F283,"Đã phủ") | D22: =COUNTIF('Anh xa'!E2:E725,A22)
A23: Bộ nhớ & nén (MEM-42) | B23: =COUNTIF('Yeu cau'!B2:B283,A23) | C23: =COUNTIFS('Yeu cau'!B2:B283,A23,'Yeu cau'!F2:F283,"Đã phủ") | D23: =COUNTIF('Anh xa'!E2:E725,A23)
A24: Nạp & trích xuất (ING-43) | B24: =COUNTIF('Yeu cau'!B2:B283,A24) | C24: =COUNTIFS('Yeu cau'!B2:B283,A24,'Yeu cau'!F2:F283,"Đã phủ") | D24: =COUNTIF('Anh xa'!E2:E725,A24)
A25: Sơ đồ KiCad (SCH-44) | B25: =COUNTIF('Yeu cau'!B2:B283,A25) | C25: =COUNTIFS('Yeu cau'!B2:B283,A25,'Yeu cau'!F2:F283,"Đã phủ") | D25: =COUNTIF('Anh xa'!E2:E725,A25)
A26: Cây khối phân cấp (HIER-45) | B26: =COUNTIF('Yeu cau'!B2:B283,A26) | C26: =COUNTIFS('Yeu cau'!B2:B283,A26,'Yeu cau'!F2:F283,"Đã phủ") | D26: =COUNTIF('Anh xa'!E2:E725,A26)
